Workbook

Sheet Petunjuk
A1: Perhitungan Manual Sistem Rekomendasi Hybrid CBF + ALS - goodnews
A2: Sel hitam = rumus Excel. Sel biru = data dari proyek. Sel kuning = parameter yang boleh diubah. Rumus identik dengan src/phase2/serving.py: skor = alpha x minmax(ALS) + (1 - alpha) x minmax(TF-IDF cosine), alpha = 0,8.
A4: Sheet | B4: Isi | C4: Sumber angka
A5: 1_Data | B5: 12 artikel sampel + parameter (alpha, top_k, sesi, K) | C5: data/processed/indo/catalog.parquet - nid nyata
A6: 2_Token | B6: Token tiap artikel, satu token per kolom | C6: kolom processed_text katalog fase 2
A7: 3_TF | B7: Term Frequency: kemunculan tiap term per artikel (COUNTIF) | C7: rumus
A8: 4_IDF | B8: df dan IDF = LN((1+N)/(1+df)) + 1 (smooth_idf scikit-learn) | C8: rumus
A9: 5_TFIDF | B9: w = TF x IDF, norma L2, bobot ternormalisasi, vektor profil sesi | C9: rumus
A10: 6_Cosine | B10: Kosinus item ke profil + matriks 12x12 (dipakai blok 'Berita serupa') | C10: rumus
A11: 7_CBF | B11: Peringkat content-based; artikel profil dibuang | C11: rumus
A12: 8_ALS | B12: 128 faktor laten per artikel, profil sesi = rata-rata faktor, skor = SUMPRODUCT | C12: data/processed/indo/indo_als_item_factors.npy
A13: 9_Hybrid | B13: min-max ALS dan CBF, blend alpha = 0,8, mask artikel profil, peringkat | C13: rumus
A14: 10_Tampilan | B14: Baris kartu yang dirender web - tanpa skor (D22) | C14: rumus
A15: 11_Evaluasi | B15: NDCG, AP, MAP, Precision, Recall, F1 pada K - K diturunkan ke 5 karena hanya ada 9 kandidat | C15: rumus + 2 flag relevan (biru)
A16: 12_Cek_Naskah | B16: Rata-rata 9 titik evaluasi terkunci untuk enam metrik (NDCG, AP, MAP, Precision, Recall, F1) vs angka naskah | C16: models/indo_eval.json
A18: BATAS 1 - TF-IDF di sini di-fit pada 12 dokumen sampel agar semua sel bisa dihitung ulang dengan tangan. Produksi fit pada 67.381 dokumen train (sekitar 99 ribu term), jadi nilai kosinus di workbook identik METODENYA, tetapi tidak identik angkanya dengan yang dilayani web.
A19: BATAS 2 - min-max pada sheet 9 dijalankan atas 12 kandidat; produksi menjalankannya atas seluruh katalog efektif (17.584 item) per akun.
A20: BATAS 3 - 3 artikel profil dan 2 artikel relevan adalah skenario ilustrasi, bukan akun simulasi. Angka evaluasi resmi ada di sheet 12_Cek_Naskah: 600 akun, 9 titik, grid alpha 0,2-0,8.
A21: URUTAN FAKTOR - baris faktor ALS mengikuti urutan nid terurut pada train (build_csr); di workbook dipakai posisi katalog.

Sheet 1_Data
A1: 1 - Data artikel sampel dan parameter
A2: Kolom Teks = processed_text persis di katalog; inilah input TF-IDF (sudah lowercase, tanpa tanda baca, tanpa stopword, tanpa stemming).
A4: Pos | B4: nid | C4: Judul | D4: Kategori | E4: Sumber | F4: Terbit | G4: Teks (input TF-IDF) | H4: Sesi? | I4: Relevan? | K4: Parameter | L4: Nilai | M4: Keterangan
A5: 1 | B5: I2d5df0726f | C5: Embung Pekayon | D5: Multimedia | E5: tempo | F5: 45940 | G5: embung pekayon pasar rebo jakarta timur oktober embung buka desember berfungsi kendali banjir sekaligus jadi sarana interaksi publik tempat rekreasi area olahraga pancing tempo fardi bestari | H5: Ya | I5: - | K5: alpha (bobot ALS) | L5: 0.8 | M5: cf_weight, configs/indo_serving.yaml
A6: 2 | B6: I0f3340d602 | C6: Israel dan Hamas Bertukar Sandera Hari Ini | D6: Multimedia | E6: tempo | F6: 45943 | G6: israel hamas tukar sandera tahan palestina hari senin oktober tukar sandera langkah penting gencat senjata dua belah pihak sekarang berlaku foto fotoeditor ryan maulana ryan maulana editor tempo co videographer | H6: Ya | I6: - | K6: bobot CBF (1 - alpha) | L6: =1-L5 | M6: 1 - alpha
A7: 3 | B7: Ic3f4f2512e | C7: 80 Kabupaten Bersaing di SIPP Award 2025 untuk Pembangunan Berkelanjutan | D7: Multimedia | E7: tempo | F7: 45925 | G7: banyak kabupaten saing sipp award dorong bangun rendah karbon berkelanjutan salah satu terima harga kepala bappeda bangka tengah joko triadhi komitmen kembang komoditas ramah lingkung kelapa kopi cokelat zulfikar epriyadi editor muhammad iqbal videographer | H7: - | I7: - | K7: top_k | L7: 10 | M7: default serving
A8: 4 | B8: Ifa9f81c923 | C8: Kontroversi Erick Thohir Selama Jadi Menteri BUMN | D8: Multimedia | E8: tempo | F8: 45917 | G8: lama jabat menteri bumn erick thohir dera sejumlah isu kontroversi anyar sorot masuk menteri rangkap jabat kabinet perintah prabowo zulfikar epriyadi editor youtube videographer | H8: Ya | I8: - | K8: N dokumen sampel | L8: =COUNT(A5:A16) | M8: dipakai 4_IDF
A9: 5 | B9: I1d82a5e6ee | C9: Sayonara, Sri Mulyani | D9: Multimedia | E9: tempo | F9: 45912 | G9: mantan menteri uang sri mulyani indrawati sapa pegawai menteri uang jakarta september tiga periode sri mulyani lagi jabat menteri uang ganti purbaya yudhi sadewa lantik presiden prabowo subianto september tempo ilham balindra | H9: - | I9: - | K9: jumlah term unik | L9: =COUNTA('3_TF'!A6:A225) | M9: kosakata
A10: 6 | B10: Ib13654bb81 | C10: Seribu Senjata | D10: Multimedia | E10: tempo | F10: 45940 | G10: atraksi pesawat ingat ulang tahun tentara nasional indonesia monumen nasional jakarta oktober upacara ulang tahun tni libat ribu prajurit lebih ribu alat utama sistem tahan angkat udara darat laut tempo ilham balindra | H10: - | I10: - | K10: dimensi faktor ALS | L10: 128 | M10: model indo_als
A11: 7 | B11: I5259c70cfc | C11: Bak Orang | D11: Multimedia | E11: tempo | F11: 45926 | G11: petugas tangan prasarana sarana umum menaiki mobil dinas bak buka jalan sudirman jakarta september undang undang lalu lintas angkut jalan nomor tahun larang mobil bak buka angkut orang jalan raya tempo imam sukamto | H11: - | I11: - | K11: K evaluasi | L11: 5 | M11: metrik @10
A12: 8 | B12: I67dbbb2a6e | C12: Mengenal Puthul, Serangga Sumber Protein Warga Gunungkidul | D12: Multimedia | E12: tempo | F12: 45949 | G12: warga gunungkidul memiliki waris rasa lokal manfaat apa alam jelang musim hujan banyak warga gunungkidul buru serangga puthul jadi sumber protein jual tambah video imam prasetyo nugroho rayyan suwanti ryan maulana editor videographer | H12: - | I12: Ya | K12: artikel profil sesi | L12: pos 1, 2, 4 | M12: sudah dibaca -> dimask
A13: 9 | B13: I307e7d7249 | C13: Panah Ikan | D13: Multimedia | E13: tempo | F13: 45940 | G13: nelayan suku bajo ditemani anak tangkap gurita air mola selatan wakatobi sulawesi tenggara oktober nelayan bajo tangkap ikan bekal panah suku hidup laut tahan selam waktu lama jalan dasar laut buru ikan jojon | H13: - | I13: Ya | K13: artikel relevan | L13: pos 8, 9 | M13: untuk sheet 11
A14: 10 | B14: I99144f9b4e | C14: Program Mobil Nasional Diusulkan Jadi Proyek Strategis Nasional | D14: Multimedia | E14: tempo | F14: 45951 | G14: menteri industri agus gumiwang kartasasmita kata menteri usul program mobil nasional minta presiden prabowo subianto jadi proyek strategis nasional psn foto tempo imam sukamto editor ryan maulana ryan maulana editor tempo co videographer | H14: - | I14: -
A15: 11 | B15: I01684f5bad | C15: Dua Jenazah Santri Korban Ponpes Al Khoziny Ambruk Diidentifikasi | D15: Multimedia | E15: tempo | F15: 45936 | G15: ridi eka saputra editor videographer | H15: - | I15: -
A16: 12 | B16: I18ca3d0ae0 | C16: Gagal Menuju Gaza, Delegasi Indonesia Dalam Misi GSF Tiba di Tanah Air | D16: Multimedia | E16: tempo | F16: 45935 | G16: ridi eka saputra editor videographer | H16: - | I16: -

Sheet 2_Token
A1: 2 - Token per artikel
A2: Satu token per kolom. Tokenisasi = pemisahan spasi; pola scikit-learn \b\w\w+\b otomatis terpenuhi karena korpus sudah lowercase, tanpa tanda baca, dan tanpa token satu huruf. Tidak ada stemming dan tidak ada stopword.
A4: Pos | B4: nid | C4: Sesi? | D4: t1 | E4: t2 | F4: t3 | G4: t4 | H4: t5 | I4: t6 | J4: t7 | K4: t8 | L4: t9 | M4: t10 | N4: t11 | O4: t12 | P4: t13 | Q4: t14 | R4: t15 | S4: t16 | T4: t17 | U4: t18 | V4: t19 | W4: t20 | X4: t21 | Y4: t22 | Z4: t23 | AA4: t24 | AB4: t25 | AC4: t26 | AD4: t27 | AE4: t28 | AF4: t29 | AG4: t30 | AH4: t31 | AI4: t32 | AJ4: t33 | AK4: t34
A5: 1 | B5: I2d5df0726f | C5: Ya | D5: embung | E5: pekayon | F5: pasar | G5: rebo | H5: jakarta | I5: timur | J5: oktober | K5: embung | L5: buka | M5: desember | N5: berfungsi | O5: kendali | P5: banjir | Q5: sekaligus | R5: jadi | S5: sarana | T5: interaksi | U5: publik | V5: tempat | W5: rekreasi | X5: area | Y5: olahraga | Z5: pancing | AA5: tempo | AB5: fardi | AC5: bestari
A6: 2 | B6: I0f3340d602 | C6: Ya | D6: israel | E6: hamas | F6: tukar | G6: sandera | H6: tahan | I6: palestina | J6: hari | K6: senin | L6: oktober | M6: tukar | N6: sandera | O6: langkah | P6: penting | Q6: gencat | R6: senjata | S6: dua | T6: belah | U6: pihak | V6: sekarang | W6: berlaku | X6: foto | Y6: fotoeditor | Z6: ryan | AA6: maulana | AB6: ryan | AC6: maulana | AD6: editor | AE6: tempo | AF6: co | AG6: videographer
A7: 3 | B7: Ic3f4f2512e | C7: - | D7: banyak | E7: kabupaten | F7: saing | G7: sipp | H7: award | I7: dorong | J7: bangun | K7: rendah | L7: karbon | M7: berkelanjutan | N7: salah | O7: satu | P7: terima | Q7: harga | R7: kepala | S7: bappeda | T7: bangka | U7: tengah | V7: joko | W7: triadhi | X7: komitmen | Y7: kembang | Z7: komoditas | AA7: ramah | AB7: lingkung | AC7: kelapa | AD7: kopi | AE7: cokelat | AF7: zulfikar | AG7: epriyadi | AH7: editor | AI7: muhammad | AJ7: iqbal | AK7: videographer
A8: 4 | B8: Ifa9f81c923 | C8: Ya | D8: lama | E8: jabat | F8: menteri | G8: bumn | H8: erick | I8: thohir | J8: dera | K8: sejumlah | L8: isu | M8: kontroversi | N8: anyar | O8: sorot | P8: masuk | Q8: menteri | R8: rangkap | S8: jabat | T8: kabinet | U8: perintah | V8: prabowo | W8: zulfikar | X8: epriyadi | Y8: editor | Z8: youtube | AA8: videographer
A9: 5 | B9: I1d82a5e6ee | C9: - | D9: mantan | E9: menteri | F9: uang | G9: sri | H9: mulyani | I9: indrawati | J9: sapa | K9: pegawai | L9: menteri | M9: uang | N9: jakarta | O9: september | P9: tiga | Q9: periode | R9: sri | S9: mulyani | T9: lagi | U9: jabat | V9: menteri | W9: uang | X9: ganti | Y9: purbaya | Z9: yudhi | AA9: sadewa | AB9: lantik | AC9: presiden | AD9: prabowo | AE9: subianto | AF9: september | AG9: tempo | AH9: ilham | AI9: balindra
A10: 6 | B10: Ib13654bb81 | C10: - | D10: atraksi | E10: pesawat | F10: ingat | G10: ulang | H10: tahun | I10: tentara | J10: nasional | K10: indonesia | L10: monumen | M10: nasional | N10: jakarta | O10: oktober | P10: upacara | Q10: ulang | R10: tahun | S10: tni | T10: libat | U10: ribu | V10: prajurit | W10: lebih | X10: ribu | Y10: alat | Z10: utama | AA10: sistem | AB10: tahan | AC10: angkat | AD10: udara | AE10: darat | AF10: laut | AG10: tempo | AH10: ilham | AI10: balindra
A11: 7 | B11: I5259c70cfc | C11: - | D11: petugas | E11: tangan | F11: prasarana | G11: sarana | H11: umum | I11: menaiki | J11: mobil | K11: dinas | L11: bak | M11: buka | N11: jalan | O11: sudirman | P11: jakarta | Q11: september | R11: undang | S11: undang | T11: lalu | U11: lintas | V11: angkut | W11: jalan | X11: nomor | Y11: tahun | Z11: larang | AA11: mobil | AB11: bak | AC11: buka | AD11: angkut | AE11: orang | AF11: jalan | AG11: raya | AH11: tempo | AI11: imam | AJ11: sukamto
A12: 8 | B12: I67dbbb2a6e | C12: - | D12: warga | E12: gunungkidul | F12: memiliki | G12: waris | H12: rasa | I12: lokal | J12: manfaat | K12: apa | L12: alam | M12: jelang | N12: musim | O12: hujan | P12: banyak | Q12: warga | R12: gunungkidul | S12: buru | T12: serangga | U12: puthul | V12: jadi | W12: sumber | X12: protein | Y12: jual | Z12: tambah | AA12: video | AB12: imam | AC12: prasetyo | AD12: nugroho | AE12: rayyan | AF12: suwanti | AG12: ryan | AH12: maulana | AI12: editor | AJ12: videographer
A13: 9 | B13: I307e7d7249 | C13: - | D13: nelayan | E13: suku | F13: bajo | G13: ditemani | H13: anak | I13: tangkap | J13: gurita | K13: air | L13: mola | M13: selatan | N13: wakatobi | O13: sulawesi | P13: tenggara | Q13: oktober | R13: nelayan | S13: bajo | T13: tangkap | U13: ikan | V13: bekal | W13: panah | X13: suku | Y13: hidup | Z13: laut | AA13: tahan | AB13: selam | AC13: waktu | AD13: lama | AE13: jalan | AF13: dasar | AG13: laut | AH13: buru | AI13: ikan | AJ13: jojon
A14: 10 | B14: I99144f9b4e | C14: - | D14: menteri | E14: industri | F14: agus | G14: gumiwang | H14: kartasasmita | I14: kata | J14: menteri | K14: usul | L14: program | M14: mobil | N14: nasional | O14: minta | P14: presiden | Q14: prabowo | R14: subianto | S14: jadi | T14: proyek | U14: strategis | V14: nasional | W14: psn | X14: foto | Y14: tempo | Z14: imam | AA14: sukamto | AB14: editor | AC14: ryan | AD14: maulana | AE14: ryan | AF14: maulana | AG14: editor | AH14: tempo | AI14: co | AJ14: videographer
A15: 11 | B15: I01684f5bad | C15: - | D15: ridi | E15: eka | F15: saputra | G15: editor | H15: videographer
A16: 12 | B16: I18ca3d0ae0 | C16: - | D16: ridi | E16: eka | F16: saputra | G16: editor | H16: videographer

Sheet 3_TF
A1: 3 - Term Frequency (TF mentah)
A2: TF = jumlah kemunculan term pada artikel, dihitung COUNTIF ke baris token di 2_Token. scikit-learn tidak membagi TF dengan panjang dokumen (sublinear_tf = False).
A4: Term | B4: pos 1 | C4: pos 2 | D4: pos 3 | E4: pos 4 | F4: pos 5 | G4: pos 6 | H4: pos 7 | I4: pos 8 | J4: pos 9 | K4: pos 10 | L4: pos 11 | M4: pos 12 | N4: Total
A6: agus | B6: =COUNTIF('2_Token'!$D$5:$AK$5,$A6) | C6: =COUNTIF('2_Token'!$D$6:$AK$6,$A6) | D6: =COUNTIF('2_Token'!$D$7:$AK$7,$A6) | E6: =COUNTIF('2_Token'!$D$8:$AK$8,$A6) | F6: =COUNTIF('2_Token'!$D$9:$AK$9,$A6) | G6: =COUNTIF('2_Token'!$D$10:$AK$10,$A6) | H6: =COUNTIF('2_Token'!$D$11:$AK$11,$A6) | I6: =COUNTIF('2_Token'!$D$12:$AK$12,$A6) | J6: =COUNTIF('2_Token'!$D$13:$AK$13,$A6) | K6: =COUNTIF('2_Token'!$D$14:$AK$14,$A6) | L6: =COUNTIF('2_Token'!$D$15:$AK$15,$A6) | M6: =COUNTIF('2_Token'!$D$16:$AK$16,$A6) | N6: =SUM(B6:M6)
A7: air | B7: =COUNTIF('2_Token'!$D$5:$AK$5,$A7) | C7: =COUNTIF('2_Token'!$D$6:$AK$6,$A7) | D7: =COUNTIF('2_Token'!$D$7:$AK$7,$A7) | E7: =COUNTIF('2_Token'!$D$8:$AK$8,$A7) | F7: =COUNTIF('2_Token'!$D$9:$AK$9,$A7) | G7: =COUNTIF('2_Token'!$D$10:$AK$10,$A7) | H7: =COUNTIF('2_Token'!$D$11:$AK$11,$A7) | I7: =COUNTIF('2_Token'!$D$12:$AK$12,$A7) | J7: =COUNTIF('2_Token'!$D$13:$AK$13,$A7) | K7: =COUNTIF('2_Token'!$D$14:$AK$14,$A7) | L7: =COUNTIF('2_Token'!$D$15:$AK$15,$A7) | M7: =COUNTIF('2_Token'!$D$16:$AK$16,$A7) | N7: =SUM(B7:M7)
A8: alam | B8: =COUNTIF('2_Token'!$D$5:$AK$5,$A8) | C8: =COUNTIF('2_Token'!$D$6:$AK$6,$A8) | D8: =COUNTIF('2_Token'!$D$7:$AK$7,$A8) | E8: =COUNTIF('2_Token'!$D$8:$AK$8,$A8) | F8: =COUNTIF('2_Token'!$D$9:$AK$9,$A8) | G8: =COUNTIF('2_Token'!$D$10:$AK$10,$A8) | H8: =COUNTIF('2_Token'!$D$11:$AK$11,$A8) | I8: =COUNTIF('2_Token'!$D$12:$AK$12,$A8) | J8: =COUNTIF('2_Token'!$D$13:$AK$13,$A8) | K8: =COUNTIF('2_Token'!$D$14:$AK$14,$A8) | L8: =COUNTIF('2_Token'!$D$15:$AK$15,$A8) | M8: =COUNTIF('2_Token'!$D$16:$AK$16,$A8) | N8: =SUM(B8:M8)
A9: alat | B9: =COUNTIF('2_Token'!$D$5:$AK$5,$A9) | C9: =COUNTIF('2_Token'!$D$6:$AK$6,$A9) | D9: =COUNTIF('2_Token'!$D$7:$AK$7,$A9) | E9: =COUNTIF('2_Token'!$D$8:$AK$8,$A9) | F9: =COUNTIF('2_Token'!$D$9:$AK$9,$A9) | G9: =COUNTIF('2_Token'!$D$10:$AK$10,$A9) | H9: =COUNTIF('2_Token'!$D$11:$AK$11,$A9) | I9: =COUNTIF('2_Token'!$D$12:$AK$12,$A9) | J9: =COUNTIF('2_Token'!$D$13:$AK$13,$A9) | K9: =COUNTIF('2_Token'!$D$14:$AK$14,$A9) | L9: =COUNTIF('2_Token'!$D$15:$AK$15,$A9) | M9: =COUNTIF('2_Token'!$D$16:$AK$16,$A9) | N9: =SUM(B9:M9)
A10: anak | B10: =COUNTIF('2_Token'!$D$5:$AK$5,$A10) | C10: =COUNTIF('2_Token'!$D$6:$AK$6,$A10) | D10: =COUNTIF('2_Token'!$D$7:$AK$7,$A10) | E10: =COUNTIF('2_Token'!$D$8:$AK$8,$A10) | F10: =COUNTIF('2_Token'!$D$9:$AK$9,$A10) | G10: =COUNTIF('2_Token'!$D$10:$AK$10,$A10) | H10: =COUNTIF('2_Token'!$D$11:$AK$11,$A10) | I10: =COUNTIF('2_Token'!$D$12:$AK$12,$A10) | J10: =COUNTIF('2_Token'!$D$13:$AK$13,$A10) | K10: =COUNTIF('2_Token'!$D$14:$AK$14,$A10) | L10: =COUNTIF('2_Token'!$D$15:$AK$15,$A10) | M10: =COUNTIF('2_Token'!$D$16:$AK$16,$A10) | N10: =SUM(B10:M10)
A11: angkat | B11: =COUNTIF('2_Token'!$D$5:$AK$5,$A11) | C11: =COUNTIF('2_Token'!$D$6:$AK$6,$A11) | D11: =COUNTIF('2_Token'!$D$7:$AK$7,$A11) | E11: =COUNTIF('2_Token'!$D$8:$AK$8,$A11) | F11: =COUNTIF('2_Token'!$D$9:$AK$9,$A11) | G11: =COUNTIF('2_Token'!$D$10:$AK$10,$A11) | H11: =COUNTIF('2_Token'!$D$11:$AK$11,$A11) | I11: =COUNTIF('2_Token'!$D$12:$AK$12,$A11) | J11: =COUNTIF('2_Token'!$D$13:$AK$13,$A11) | K11: =COUNTIF('2_Token'!$D$14:$AK$14,$A11) | L11: =COUNTIF('2_Token'!$D$15:$AK$15,$A11) | M11: =COUNTIF('2_Token'!$D$16:$AK$16,$A11) | N11: =SUM(B11:M11)
A12: angkut | B12: =COUNTIF('2_Token'!$D$5:$AK$5,$A12) | C12: =COUNTIF('2_Token'!$D$6:$AK$6,$A12) | D12: =COUNTIF('2_Token'!$D$7:$AK$7,$A12) | E12: =COUNTIF('2_Token'!$D$8:$AK$8,$A12) | F12: =COUNTIF('2_Token'!$D$9:$AK$9,$A12) | G12: =COUNTIF('2_Token'!$D$10:$AK$10,$A12) | H12: =COUNTIF('2_Token'!$D$11:$AK$11,$A12) | I12: =COUNTIF('2_Token'!$D$12:$AK$12,$A12) | J12: =COUNTIF('2_Token'!$D$13:$AK$13,$A12) | K12: =COUNTIF('2_Token'!$D$14:$AK$14,$A12) | L12: =COUNTIF('2_Token'!$D$15:$AK$15,$A12) | M12: =COUNTIF('2_Token'!$D$16:$AK$16,$A12) | N12: =SUM(B12:M12)
A13: anyar | B13: =COUNTIF('2_Token'!$D$5:$AK$5,$A13) | C13: =COUNTIF('2_Token'!$D$6:$AK$6,$A13) | D13: =COUNTIF('2_Token'!$D$7:$AK$7,$A13) | E13: =COUNTIF('2_Token'!$D$8:$AK$8,$A13) | F13: =COUNTIF('2_Token'!$D$9:$AK$9,$A13) | G13: =COUNTIF('2_Token'!$D$10:$AK$10,$A13) | H13: =COUNTIF('2_Token'!$D$11:$AK$11,$A13) | I13: =COUNTIF('2_Token'!$D$12:$AK$12,$A13) | J13: =COUNTIF('2_Token'!$D$13:$AK$13,$A13) | K13: =COUNTIF('2_Token'!$D$14:$AK$14,$A13) | L13: =COUNTIF('2_Token'!$D$15:$AK$15,$A13) | M13: =COUNTIF('2_Token'!$D$16:$AK$16,$A13) | N13: =SUM(B13:M13)
A14: apa | B14: =COUNTIF('2_Token'!$D$5:$AK$5,$A14) | C14: =COUNTIF('2_Token'!$D$6:$AK$6,$A14) | D14: =COUNTIF('2_Token'!$D$7:$AK$7,$A14) | E14: =COUNTIF('2_Token'!$D$8:$AK$8,$A14) | F14: =COUNTIF('2_Token'!$D$9:$AK$9,$A14) | G14: =COUNTIF('2_Token'!$D$10:$AK$10,$A14) | H14: =COUNTIF('2_Token'!$D$11:$AK$11,$A14) | I14: =COUNTIF('2_Token'!$D$12:$AK$12,$A14) | J14: =COUNTIF('2_Token'!$D$13:$AK$13,$A14) | K14: =COUNTIF('2_Token'!$D$14:$AK$14,$A14) | L14: =COUNTIF('2_Token'!$D$15:$AK$15,$A14) | M14: =COUNTIF('2_Token'!$D$16:$AK$16,$A14) | N14: =SUM(B14:M14)
A15: area | B15: =COUNTIF('2_Token'!$D$5:$AK$5,$A15) | C15: =COUNTIF('2_Token'!$D$6:$AK$6,$A15) | D15: =COUNTIF('2_Token'!$D$7:$AK$7,$A15) | E15: =COUNTIF('2_Token'!$D$8:$AK$8,$A15) | F15: =COUNTIF('2_Token'!$D$9:$AK$9,$A15) | G15: =COUNTIF('2_Token'!$D$10:$AK$10,$A15) | H15: =COUNTIF('2_Token'!$D$11:$AK$11,$A15) | I15: =COUNTIF('2_Token'!$D$12:$AK$12,$A15) | J15: =COUNTIF('2_Token'!$D$13:$AK$13,$A15) | K15: =COUNTIF('2_Token'!$D$14:$AK$14,$A15) | L15: =COUNTIF('2_Token'!$D$15:$AK$15,$A15) | M15: =COUNTIF('2_Token'!$D$16:$AK$16,$A15) | N15: =SUM(B15:M15)
A16: atraksi | B16: =COUNTIF('2_Token'!$D$5:$AK$5,$A16) | C16: =COUNTIF('2_Token'!$D$6:$AK$6,$A16) | D16: =COUNTIF('2_Token'!$D$7:$AK$7,$A16) | E16: =COUNTIF('2_Token'!$D$8:$AK$8,$A16) | F16: =COUNTIF('2_Token'!$D$9:$AK$9,$A16) | G16: =COUNTIF('2_Token'!$D$10:$AK$10,$A16) | H16: =COUNTIF('2_Token'!$D$11:$AK$11,$A16) | I16: =COUNTIF('2_Token'!$D$12:$AK$12,$A16) | J16: =COUNTIF('2_Token'!$D$13:$AK$13,$A16) | K16: =COUNTIF('2_Token'!$D$14:$AK$14,$A16) | L16: =COUNTIF('2_Token'!$D$15:$AK$15,$A16) | M16: =COUNTIF('2_Token'!$D$16:$AK$16,$A16) | N16: =SUM(B16:M16)
A17: award | B17: =COUNTIF('2_Token'!$D$5:$AK$5,$A17) | C17: =COUNTIF('2_Token'!$D$6:$AK$6,$A17) | D17: =COUNTIF('2_Token'!$D$7:$AK$7,$A17) | E17: =COUNTIF('2_Token'!$D$8:$AK$8,$A17) | F17: =COUNTIF('2_Token'!$D$9:$AK$9,$A17) | G17: =COUNTIF('2_Token'!$D$10:$AK$10,$A17) | H17: =COUNTIF('2_Token'!$D$11:$AK$11,$A17) | I17: =COUNTIF('2_Token'!$D$12:$AK$12,$A17) | J17: =COUNTIF('2_Token'!$D$13:$AK$13,$A17) | K17: =COUNTIF('2_Token'!$D$14:$AK$14,$A17) | L17: =COUNTIF('2_Token'!$D$15:$AK$15,$A17) | M17: =COUNTIF('2_Token'!$D$16:$AK$16,$A17) | N17: =SUM(B17:M17)
... A225: zulfikar | B225: =COUNTIF('2_Token'!$D$5:$AK$5,$A225) | C225: =COUNTIF('2_Token'!$D$6:$AK$6,$A225) | D225: =COUNTIF('2_Token'!$D$7:$AK$7,$A225) | E225: =COUNTIF('2_Token'!$D$8:$AK$8,$A225) | F225: =COUNTIF('2_Token'!$D$9:$AK$9,$A225) | G225: =COUNTIF('2_Token'!$D$10:$AK$10,$A225) | H225: =COUNTIF('2_Token'!$D$11:$AK$11,$A225) | I225: =COUNTIF('2_Token'!$D$12:$AK$12,$A225) | J225: =COUNTIF('2_Token'!$D$13:$AK$13,$A225) | K225: =COUNTIF('2_Token'!$D$14:$AK$14,$A225) | L225: =COUNTIF('2_Token'!$D$15:$AK$15,$A225) | M225: =COUNTIF('2_Token'!$D$16:$AK$16,$A225) | N225: =SUM(B225:M225)
A226: Total token | B226: =SUM(B6:B225) | C226: =SUM(C6:C225) | D226: =SUM(D6:D225) | E226: =SUM(E6:E225) | F226: =SUM(F6:F225) | G226: =SUM(G6:G225) | H226: =SUM(H6:H225) | I226: =SUM(I6:I225) | ... M226: =SUM(M6:M225)

Sheet 4_IDF
A1: 4 - Document Frequency dan IDF
A2: IDF = LN((1 + N) / (1 + df)) + 1, yaitu smooth_idf bawaan TfidfVectorizer. N diambil dari 1_Data!L8.
A4: Term | B4: df | C4: (1+N)/(1+df) | D4: LN(...) | E4: IDF
A6: ='3_TF'!A6 | B6: =COUNTIF('3_TF'!B6:M6,">0") | C6: =(1+'1_Data'!$L$8)/(1+B6) | D6: =LN(C6) | E6: =D6+1
A7: ='3_TF'!A7 | B7: =COUNTIF('3_TF'!B7:M7,">0") | C7: =(1+'1_Data'!$L$8)/(1+B7) | D7: =LN(C7) | E7: =D7+1
A8: ='3_TF'!A8 | B8: =COUNTIF('3_TF'!B8:M8,">0") | C8: =(1+'1_Data'!$L$8)/(1+B8) | D8: =LN(C8) | E8: =D8+1
A9: ='3_TF'!A9 | B9: =COUNTIF('3_TF'!B9:M9,">0") | C9: =(1+'1_Data'!$L$8)/(1+B9) | D9: =LN(C9) | E9: =D9+1
A10: ='3_TF'!A10 | B10: =COUNTIF('3_TF'!B10:M10,">0") | C10: =(1+'1_Data'!$L$8)/(1+B10) | D10: =LN(C10) | E10: =D10+1
A11: ='3_TF'!A11 | B11: =COUNTIF('3_TF'!B11:M11,">0") | C11: =(1+'1_Data'!$L$8)/(1+B11) | D11: =LN(C11) | E11: =D11+1
A12: ='3_TF'!A12 | B12: =COUNTIF('3_TF'!B12:M12,">0") | C12: =(1+'1_Data'!$L$8)/(1+B12) | D12: =LN(C12) | E12: =D12+1
A13: ='3_TF'!A13 | B13: =COUNTIF('3_TF'!B13:M13,">0") | C13: =(1+'1_Data'!$L$8)/(1+B13) | D13: =LN(C13) | E13: =D13+1
A14: ='3_TF'!A14 | B14: =COUNTIF('3_TF'!B14:M14,">0") | C14: =(1+'1_Data'!$L$8)/(1+B14) | D14: =LN(C14) | E14: =D14+1
A15: ='3_TF'!A15 | B15: =COUNTIF('3_TF'!B15:M15,">0") | C15: =(1+'1_Data'!$L$8)/(1+B15) | D15: =LN(C15) | E15: =D15+1
A16: ='3_TF'!A16 | B16: =COUNTIF('3_TF'!B16:M16,">0") | C16: =(1+'1_Data'!$L$8)/(1+B16) | D16: =LN(C16) | E16: =D16+1
A17: ='3_TF'!A17 | B17: =COUNTIF('3_TF'!B17:M17,">0") | C17: =(1+'1_Data'!$L$8)/(1+B17) | D17: =LN(C17) | E17: =D17+1
... A225: ='3_TF'!A225 | B225: =COUNTIF('3_TF'!B225:M225,">0") | C225: =(1+'1_Data'!$L$8)/(1+B225) | D225: =LN(C225) | E225: =D225+1

Sheet 5_TFIDF
A1: 5 - Bobot TF-IDF dan normalisasi L2
A2: Kiri: w = TF x IDF. Baris 'norma' = SQRT(SUMSQ(kolom)). Kanan: w / norma. Kolom profil = rata-rata vektor ternormalisasi dari 3 artikel sesi (sesuai _cbf_scores).
A4: Term | B4: w pos 1 | C4: w pos 2 | D4: w pos 3 | E4: w pos 4 | F4: w pos 5 | G4: w pos 6 | H4: w pos 7 | I4: w pos 8 | J4: w pos 9 | K4: w pos 10 | L4: w pos 11 | M4: w pos 12 | O4: Term | P4: n pos 1 | Q4: n pos 2 | R4: n pos 3 | S4: n pos 4 | T4: n pos 5 | U4: n pos 6 | V4: n pos 7 | W4: n pos 8 | X4: n pos 9 | Y4: n pos 10 | Z4: n pos 11 | AA4: n pos 12 | AB4: profil
A6: ='3_TF'!A6 | B6: ='3_TF'!B6*'4_IDF'!$E6 | C6: ='3_TF'!C6*'4_IDF'!$E6 | D6: ='3_TF'!D6*'4_IDF'!$E6 | E6: ='3_TF'!E6*'4_IDF'!$E6 | F6: ='3_TF'!F6*'4_IDF'!$E6 | G6: ='3_TF'!G6*'4_IDF'!$E6 | H6: ='3_TF'!H6*'4_IDF'!$E6 | I6: ='3_TF'!I6*'4_IDF'!$E6 | ... M6: ='3_TF'!M6*'4_IDF'!$E6 | O6: =A6 | P6: =IF(B$227=0,0,B6/B$227) | Q6: =IF(C$227=0,0,C6/C$227) | R6: =IF(D$227=0,0,D6/D$227) | S6: =IF(E$227=0,0,E6/E$227) | T6: =IF(F$227=0,0,F6/F$227) | U6: =IF(G$227=0,0,G6/G$227) | V6: =IF(H$227=0,0,H6/H$227) | W6: =IF(I$227=0,0,I6/I$227) | ... AA6: =IF(M$227=0,0,M6/M$227) | AB6: =AVERAGE(P6,Q6,S6)
A7: ='3_TF'!A7 | B7: ='3_TF'!B7*'4_IDF'!$E7 | C7: ='3_TF'!C7*'4_IDF'!$E7 | D7: ='3_TF'!D7*'4_IDF'!$E7 | E7: ='3_TF'!E7*'4_IDF'!$E7 | F7: ='3_TF'!F7*'4_IDF'!$E7 | G7: ='3_TF'!G7*'4_IDF'!$E7 | H7: ='3_TF'!H7*'4_IDF'!$E7 | I7: ='3_TF'!I7*'4_IDF'!$E7 | ... M7: ='3_TF'!M7*'4_IDF'!$E7 | O7: =A7 | P7: =IF(B$227=0,0,B7/B$227) | Q7: =IF(C$227=0,0,C7/C$227) | R7: =IF(D$227=0,0,D7/D$227) | S7: =IF(E$227=0,0,E7/E$227) | T7: =IF(F$227=0,0,F7/F$227) | U7: =IF(G$227=0,0,G7/G$227) | V7: =IF(H$227=0,0,H7/H$227) | W7: =IF(I$227=0,0,I7/I$227) | ... AA7: =IF(M$227=0,0,M7/M$227) | AB7: =AVERAGE(P7,Q7,S7)
A8: ='3_TF'!A8 | B8: ='3_TF'!B8*'4_IDF'!$E8 | C8: ='3_TF'!C8*'4_IDF'!$E8 | D8: ='3_TF'!D8*'4_IDF'!$E8 | E8: ='3_TF'!E8*'4_IDF'!$E8 | F8: ='3_TF'!F8*'4_IDF'!$E8 | G8: ='3_TF'!G8*'4_IDF'!$E8 | H8: ='3_TF'!H8*'4_IDF'!$E8 | I8: ='3_TF'!I8*'4_IDF'!$E8 | ... M8: ='3_TF'!M8*'4_IDF'!$E8 | O8: =A8 | P8: =IF(B$227=0,0,B8/B$227) | Q8: =IF(C$227=0,0,C8/C$227) | R8: =IF(D$227=0,0,D8/D$227) | S8: =IF(E$227=0,0,E8/E$227) | T8: =IF(F$227=0,0,F8/F$227) | U8: =IF(G$227=0,0,G8/G$227) | V8: =IF(H$227=0,0,H8/H$227) | W8: =IF(I$227=0,0,I8/I$227) | ... AA8: =IF(M$227=0,0,M8/M$227) | AB8: =AVERAGE(P8,Q8,S8)
A9: ='3_TF'!A9 | B9: ='3_TF'!B9*'4_IDF'!$E9 | C9: ='3_TF'!C9*'4_IDF'!$E9 | D9: ='3_TF'!D9*'4_IDF'!$E9 | E9: ='3_TF'!E9*'4_IDF'!$E9 | F9: ='3_TF'!F9*'4_IDF'!$E9 | G9: ='3_TF'!G9*'4_IDF'!$E9 | H9: ='3_TF'!H9*'4_IDF'!$E9 | I9: ='3_TF'!I9*'4_IDF'!$E9 | ... M9: ='3_TF'!M9*'4_IDF'!$E9 | O9: =A9 | P9: =IF(B$227=0,0,B9/B$227) | Q9: =IF(C$227=0,0,C9/C$227) | R9: =IF(D$227=0,0,D9/D$227) | S9: =IF(E$227=0,0,E9/E$227) | T9: =IF(F$227=0,0,F9/F$227) | U9: =IF(G$227=0,0,G9/G$227) | V9: =IF(H$227=0,0,H9/H$227) | W9: =IF(I$227=0,0,I9/I$227) | ... AA9: =IF(M$227=0,0,M9/M$227) | AB9: =AVERAGE(P9,Q9,S9)
A10: ='3_TF'!A10 | B10: ='3_TF'!B10*'4_IDF'!$E10 | C10: ='3_TF'!C10*'4_IDF'!$E10 | D10: ='3_TF'!D10*'4_IDF'!$E10 | E10: ='3_TF'!E10*'4_IDF'!$E10 | F10: ='3_TF'!F10*'4_IDF'!$E10 | G10: ='3_TF'!G10*'4_IDF'!$E10 | H10: ='3_TF'!H10*'4_IDF'!$E10 | I10: ='3_TF'!I10*'4_IDF'!$E10 | ... M10: ='3_TF'!M10*'4_IDF'!$E10 | O10: =A10 | P10: =IF(B$227=0,0,B10/B$227) | Q10: =IF(C$227=0,0,C10/C$227) | R10: =IF(D$227=0,0,D10/D$227) | S10: =IF(E$227=0,0,E10/E$227) | T10: =IF(F$227=0,0,F10/F$227) | U10: =IF(G$227=0,0,G10/G$227) | V10: =IF(H$227=0,0,H10/H$227) | W10: =IF(I$227=0,0,I10/I$227) | ... AA10: =IF(M$227=0,0,M10/M$227) | AB10: =AVERAGE(P10,Q10,S10)
A11: ='3_TF'!A11 | B11: ='3_TF'!B11*'4_IDF'!$E11 | C11: ='3_TF'!C11*'4_IDF'!$E11 | D11: ='3_TF'!D11*'4_IDF'!$E11 | E11: ='3_TF'!E11*'4_IDF'!$E11 | F11: ='3_TF'!F11*'4_IDF'!$E11 | G11: ='3_TF'!G11*'4_IDF'!$E11 | H11: ='3_TF'!H11*'4_IDF'!$E11 | I11: ='3_TF'!I11*'4_IDF'!$E11 | ... M11: ='3_TF'!M11*'4_IDF'!$E11 | O11: =A11 | P11: =IF(B$227=0,0,B11/B$227) | Q11: =IF(C$227=0,0,C11/C$227) | R11: =IF(D$227=0,0,D11/D$227) | S11: =IF(E$227=0,0,E11/E$227) | T11: =IF(F$227=0,0,F11/F$227) | U11: =IF(G$227=0,0,G11/G$227) | V11: =IF(H$227=0,0,H11/H$227) | W11: =IF(I$227=0,0,I11/I$227) | ... AA11: =IF(M$227=0,0,M11/M$227) | AB11: =AVERAGE(P11,Q11,S11)
A12: ='3_TF'!A12 | B12: ='3_TF'!B12*'4_IDF'!$E12 | C12: ='3_TF'!C12*'4_IDF'!$E12 | D12: ='3_TF'!D12*'4_IDF'!$E12 | E12: ='3_TF'!E12*'4_IDF'!$E12 | F12: ='3_TF'!F12*'4_IDF'!$E12 | G12: ='3_TF'!G12*'4_IDF'!$E12 | H12: ='3_TF'!H12*'4_IDF'!$E12 | I12: ='3_TF'!I12*'4_IDF'!$E12 | ... M12: ='3_TF'!M12*'4_IDF'!$E12 | O12: =A12 | P12: =IF(B$227=0,0,B12/B$227) | Q12: =IF(C$227=0,0,C12/C$227) | R12: =IF(D$227=0,0,D12/D$227) | S12: =IF(E$227=0,0,E12/E$227) | T12: =IF(F$227=0,0,F12/F$227) | U12: =IF(G$227=0,0,G12/G$227) | V12: =IF(H$227=0,0,H12/H$227) | W12: =IF(I$227=0,0,I12/I$227) | ... AA12: =IF(M$227=0,0,M12/M$227) | AB12: =AVERAGE(P12,Q12,S12)
A13: ='3_TF'!A13 | B13: ='3_TF'!B13*'4_IDF'!$E13 | C13: ='3_TF'!C13*'4_IDF'!$E13 | D13: ='3_TF'!D13*'4_IDF'!$E13 | E13: ='3_TF'!E13*'4_IDF'!$E13 | F13: ='3_TF'!F13*'4_IDF'!$E13 | G13: ='3_TF'!G13*'4_IDF'!$E13 | H13: ='3_TF'!H13*'4_IDF'!$E13 | I13: ='3_TF'!I13*'4_IDF'!$E13 | ... M13: ='3_TF'!M13*'4_IDF'!$E13 | O13: =A13 | P13: =IF(B$227=0,0,B13/B$227) | Q13: =IF(C$227=0,0,C13/C$227) | R13: =IF(D$227=0,0,D13/D$227) | S13: =IF(E$227=0,0,E13/E$227) | T13: =IF(F$227=0,0,F13/F$227) | U13: =IF(G$227=0,0,G13/G$227) | V13: =IF(H$227=0,0,H13/H$227) | W13: =IF(I$227=0,0,I13/I$227) | ... AA13: =IF(M$227=0,0,M13/M$227) | AB13: =AVERAGE(P13,Q13,S13)
A14: ='3_TF'!A14 | B14: ='3_TF'!B14*'4_IDF'!$E14 | C14: ='3_TF'!C14*'4_IDF'!$E14 | D14: ='3_TF'!D14*'4_IDF'!$E14 | E14: ='3_TF'!E14*'4_IDF'!$E14 | F14: ='3_TF'!F14*'4_IDF'!$E14 | G14: ='3_TF'!G14*'4_IDF'!$E14 | H14: ='3_TF'!H14*'4_IDF'!$E14 | I14: ='3_TF'!I14*'4_IDF'!$E14 | ... M14: ='3_TF'!M14*'4_IDF'!$E14 | O14: =A14 | P14: =IF(B$227=0,0,B14/B$227) | Q14: =IF(C$227=0,0,C14/C$227) | R14: =IF(D$227=0,0,D14/D$227) | S14: =IF(E$227=0,0,E14/E$227) | T14: =IF(F$227=0,0,F14/F$227) | U14: =IF(G$227=0,0,G14/G$227) | V14: =IF(H$227=0,0,H14/H$227) | W14: =IF(I$227=0,0,I14/I$227) | ... AA14: =IF(M$227=0,0,M14/M$227) | AB14: =AVERAGE(P14,Q14,S14)
A15: ='3_TF'!A15 | B15: ='3_TF'!B15*'4_IDF'!$E15 | C15: ='3_TF'!C15*'4_IDF'!$E15 | D15: ='3_TF'!D15*'4_IDF'!$E15 | E15: ='3_TF'!E15*'4_IDF'!$E15 | F15: ='3_TF'!F15*'4_IDF'!$E15 | G15: ='3_TF'!G15*'4_IDF'!$E15 | H15: ='3_TF'!H15*'4_IDF'!$E15 | I15: ='3_TF'!I15*'4_IDF'!$E15 | ... M15: ='3_TF'!M15*'4_IDF'!$E15 | O15: =A15 | P15: =IF(B$227=0,0,B15/B$227) | Q15: =IF(C$227=0,0,C15/C$227) | R15: =IF(D$227=0,0,D15/D$227) | S15: =IF(E$227=0,0,E15/E$227) | T15: =IF(F$227=0,0,F15/F$227) | U15: =IF(G$227=0,0,G15/G$227) | V15: =IF(H$227=0,0,H15/H$227) | W15: =IF(I$227=0,0,I15/I$227) | ... AA15: =IF(M$227=0,0,M15/M$227) | AB15: =AVERAGE(P15,Q15,S15)
A16: ='3_TF'!A16 | B16: ='3_TF'!B16*'4_IDF'!$E16 | C16: ='3_TF'!C16*'4_IDF'!$E16 | D16: ='3_TF'!D16*'4_IDF'!$E16 | E16: ='3_TF'!E16*'4_IDF'!$E16 | F16: ='3_TF'!F16*'4_IDF'!$E16 | G16: ='3_TF'!G16*'4_IDF'!$E16 | H16: ='3_TF'!H16*'4_IDF'!$E16 | I16: ='3_TF'!I16*'4_IDF'!$E16 | ... M16: ='3_TF'!M16*'4_IDF'!$E16 | O16: =A16 | P16: =IF(B$227=0,0,B16/B$227) | Q16: =IF(C$227=0,0,C16/C$227) | R16: =IF(D$227=0,0,D16/D$227) | S16: =IF(E$227=0,0,E16/E$227) | T16: =IF(F$227=0,0,F16/F$227) | U16: =IF(G$227=0,0,G16/G$227) | V16: =IF(H$227=0,0,H16/H$227) | W16: =IF(I$227=0,0,I16/I$227) | ... AA16: =IF(M$227=0,0,M16/M$227) | AB16: =AVERAGE(P16,Q16,S16)
A17: ='3_TF'!A17 | B17: ='3_TF'!B17*'4_IDF'!$E17 | C17: ='3_TF'!C17*'4_IDF'!$E17 | D17: ='3_TF'!D17*'4_IDF'!$E17 | E17: ='3_TF'!E17*'4_IDF'!$E17 | F17: ='3_TF'!F17*'4_IDF'!$E17 | G17: ='3_TF'!G17*'4_IDF'!$E17 | H17: ='3_TF'!H17*'4_IDF'!$E17 | I17: ='3_TF'!I17*'4_IDF'!$E17 | ... M17: ='3_TF'!M17*'4_IDF'!$E17 | O17: =A17 | P17: =IF(B$227=0,0,B17/B$227) | Q17: =IF(C$227=0,0,C17/C$227) | R17: =IF(D$227=0,0,D17/D$227) | S17: =IF(E$227=0,0,E17/E$227) | T17: =IF(F$227=0,0,F17/F$227) | U17: =IF(G$227=0,0,G17/G$227) | V17: =IF(H$227=0,0,H17/H$227) | W17: =IF(I$227=0,0,I17/I$227) | ... AA17: =IF(M$227=0,0,M17/M$227) | AB17: =AVERAGE(P17,Q17,S17)
... A225: ='3_TF'!A225 | B225: ='3_TF'!B225*'4_IDF'!$E225 | C225: ='3_TF'!C225*'4_IDF'!$E225 | D225: ='3_TF'!D225*'4_IDF'!$E225 | E225: ='3_TF'!E225*'4_IDF'!$E225 | F225: ='3_TF'!F225*'4_IDF'!$E225 | G225: ='3_TF'!G225*'4_IDF'!$E225 | H225: ='3_TF'!H225*'4_IDF'!$E225 | I225: ='3_TF'!I225*'4_IDF'!$E225 | ... M225: ='3_TF'!M225*'4_IDF'!$E225 | O225: =A225 | P225: =IF(B$227=0,0,B225/B$227) | Q225: =IF(C$227=0,0,C225/C$227) | R225: =IF(D$227=0,0,D225/D$227) | S225: =IF(E$227=0,0,E225/E$227) | T225: =IF(F$227=0,0,F225/F$227) | U225: =IF(G$227=0,0,G225/G$227) | V225: =IF(H$227=0,0,H225/H$227) | W225: =IF(I$227=0,0,I225/I$227) | ... AA225: =IF(M$227=0,0,M225/M$227) | AB225: =AVERAGE(P225,Q225,S225)
A227: norma | B227: =SQRT(SUMSQ(B6:B225)) | C227: =SQRT(SUMSQ(C6:C225)) | D227: =SQRT(SUMSQ(D6:D225)) | E227: =SQRT(SUMSQ(E6:E225)) | F227: =SQRT(SUMSQ(F6:F225)) | G227: =SQRT(SUMSQ(G6:G225)) | H227: =SQRT(SUMSQ(H6:H225)) | I227: =SQRT(SUMSQ(I6:I225)) | ... M227: =SQRT(SUMSQ(M6:M225)) | O227: norma | P227: =SQRT(SUMSQ(P6:P225)) | Q227: =SQRT(SUMSQ(Q6:Q225)) | R227: =SQRT(SUMSQ(R6:R225)) | S227: =SQRT(SUMSQ(S6:S225)) | T227: =SQRT(SUMSQ(T6:T225)) | U227: =SQRT(SUMSQ(U6:U225)) | V227: =SQRT(SUMSQ(V6:V225)) | W227: =SQRT(SUMSQ(W6:W225)) | ... AB227: =SQRT(SUMSQ(AB6:AB225))

Sheet 6_Cosine
A1: 6 - Cosine similarity
A2: cos(item, profil) = SUMPRODUCT(item ternormalisasi, profil) / (norma item x norma profil). Tiap item sudah L2 = 1, jadi penyebutnya = norma profil. Nilai inilah yang masuk 9_Hybrid.
A4: Pos | B4: nid | C4: Sesi? | D4: cos ke profil
A5: 1 | B5: I2d5df0726f | C5: Ya | D5: =SUMPRODUCT('5_TFIDF'!$P$6:$P$225,'5_TFIDF'!$AB$6:$AB$225)/('5_TFIDF'!P$227*'5_TFIDF'!AB$227)
A6: 2 | B6: I0f3340d602 | C6: Ya | D6: =SUMPRODUCT('5_TFIDF'!$Q$6:$Q$225,'5_TFIDF'!$AB$6:$AB$225)/('5_TFIDF'!Q$227*'5_TFIDF'!AB$227)
A7: 3 | B7: Ic3f4f2512e | C7: - | D7: =SUMPRODUCT('5_TFIDF'!$R$6:$R$225,'5_TFIDF'!$AB$6:$AB$225)/('5_TFIDF'!R$227*'5_TFIDF'!AB$227)
A8: 4 | B8: Ifa9f81c923 | C8: Ya | D8: =SUMPRODUCT('5_TFIDF'!$S$6:$S$225,'5_TFIDF'!$AB$6:$AB$225)/('5_TFIDF'!S$227*'5_TFIDF'!AB$227)
A9: 5 | B9: I1d82a5e6ee | C9: - | D9: =SUMPRODUCT('5_TFIDF'!$T$6:$T$225,'5_TFIDF'!$AB$6:$AB$225)/('5_TFIDF'!T$227*'5_TFIDF'!AB$227)
A10: 6 | B10: Ib13654bb81 | C10: - | D10: =SUMPRODUCT('5_TFIDF'!$U$6:$U$225,'5_TFIDF'!$AB$6:$AB$225)/('5_TFIDF'!U$227*'5_TFIDF'!AB$227)
A11: 7 | B11: I5259c70cfc | C11: - | D11: =SUMPRODUCT('5_TFIDF'!$V$6:$V$225,'5_TFIDF'!$AB$6:$AB$225)/('5_TFIDF'!V$227*'5_TFIDF'!AB$227)
A12: 8 | B12: I67dbbb2a6e | C12: - | D12: =SUMPRODUCT('5_TFIDF'!$W$6:$W$225,'5_TFIDF'!$AB$6:$AB$225)/('5_TFIDF'!W$227*'5_TFIDF'!AB$227)
A13: 9 | B13: I307e7d7249 | C13: - | D13: =SUMPRODUCT('5_TFIDF'!$X$6:$X$225,'5_TFIDF'!$AB$6:$AB$225)/('5_TFIDF'!X$227*'5_TFIDF'!AB$227)
A14: 10 | B14: I99144f9b4e | C14: - | D14: =SUMPRODUCT('5_TFIDF'!$Y$6:$Y$225,'5_TFIDF'!$AB$6:$AB$225)/('5_TFIDF'!Y$227*'5_TFIDF'!AB$227)
A15: 11 | B15: I01684f5bad | C15: - | D15: =SUMPRODUCT('5_TFIDF'!$Z$6:$Z$225,'5_TFIDF'!$AB$6:$AB$225)/('5_TFIDF'!Z$227*'5_TFIDF'!AB$227)
A16: 12 | B16: I18ca3d0ae0 | C16: - | D16: =SUMPRODUCT('5_TFIDF'!$AA$6:$AA$225,'5_TFIDF'!$AB$6:$AB$225)/('5_TFIDF'!AA$227*'5_TFIDF'!AB$227)
A18: Matriks kosinus antar artikel - dasar blok 'Berita serupa' (similar(nid))
B19: pos 1 | C19: pos 2 | D19: pos 3 | E19: pos 4 | F19: pos 5 | G19: pos 6 | H19: pos 7 | I19: pos 8 | J19: pos 9 | K19: pos 10 | L19: pos 11 | M19: pos 12
A20: pos 1 | B20: =SUMPRODUCT('5_TFIDF'!$P$6:$P$225,'5_TFIDF'!$P$6:$P$225)/('5_TFIDF'!P$227*'5_TFIDF'!P$227) | C20: =SUMPRODUCT('5_TFIDF'!$P$6:$P$225,'5_TFIDF'!$Q$6:$Q$225)/('5_TFIDF'!P$227*'5_TFIDF'!Q$227) | D20: =SUMPRODUCT('5_TFIDF'!$P$6:$P$225,'5_TFIDF'!$R$6:$R$225)/('5_TFIDF'!P$227*'5_TFIDF'!R$227) | E20: =SUMPRODUCT('5_TFIDF'!$P$6:$P$225,'5_TFIDF'!$S$6:$S$225)/('5_TFIDF'!P$227*'5_TFIDF'!S$227) | F20: =SUMPRODUCT('5_TFIDF'!$P$6:$P$225,'5_TFIDF'!$T$6:$T$225)/('5_TFIDF'!P$227*'5_TFIDF'!T$227) | G20: =SUMPRODUCT('5_TFIDF'!$P$6:$P$225,'5_TFIDF'!$U$6:$U$225)/('5_TFIDF'!P$227*'5_TFIDF'!U$227) | H20: =SUMPRODUCT('5_TFIDF'!$P$6:$P$225,'5_TFIDF'!$V$6:$V$225)/('5_TFIDF'!P$227*'5_TFIDF'!V$227) | I20: =SUMPRODUCT('5_TFIDF'!$P$6:$P$225,'5_TFIDF'!$W$6:$W$225)/('5_TFIDF'!P$227*'5_TFIDF'!W$227) | J20: =SUMPRODUCT('5_TFIDF'!$P$6:$P$225,'5_TFIDF'!$X$6:$X$225)/('5_TFIDF'!P$227*'5_TFIDF'!X$227) | K20: =SUMPRODUCT('5_TFIDF'!$P$6:$P$225,'5_TFIDF'!$Y$6:$Y$225)/('5_TFIDF'!P$227*'5_TFIDF'!Y$227) | L20: =SUMPRODUCT('5_TFIDF'!$P$6:$P$225,'5_TFIDF'!$Z$6:$Z$225)/('5_TFIDF'!P$227*'5_TFIDF'!Z$227) | M20: =SUMPRODUCT('5_TFIDF'!$P$6:$P$225,'5_TFIDF'!$AA$6:$AA$225)/('5_TFIDF'!P$227*'5_TFIDF'!AA$227)
A21: pos 2 | B21: =SUMPRODUCT('5_TFIDF'!$Q$6:$Q$225,'5_TFIDF'!$P$6:$P$225)/('5_TFIDF'!Q$227*'5_TFIDF'!P$227) | C21: =SUMPRODUCT('5_TFIDF'!$Q$6:$Q$225,'5_TFIDF'!$Q$6:$Q$225)/('5_TFIDF'!Q$227*'5_TFIDF'!Q$227) | D21: =SUMPRODUCT('5_TFIDF'!$Q$6:$Q$225,'5_TFIDF'!$R$6:$R$225)/('5_TFIDF'!Q$227*'5_TFIDF'!R$227) | E21: =SUMPRODUCT('5_TFIDF'!$Q$6:$Q$225,'5_TFIDF'!$S$6:$S$225)/('5_TFIDF'!Q$227*'5_TFIDF'!S$227) | F21: =SUMPRODUCT('5_TFIDF'!$Q$6:$Q$225,'5_TFIDF'!$T$6:$T$225)/('5_TFIDF'!Q$227*'5_TFIDF'!T$227) | G21: =SUMPRODUCT('5_TFIDF'!$Q$6:$Q$225,'5_TFIDF'!$U$6:$U$225)/('5_TFIDF'!Q$227*'5_TFIDF'!U$227) | H21: =SUMPRODUCT('5_TFIDF'!$Q$6:$Q$225,'5_TFIDF'!$V$6:$V$225)/('5_TFIDF'!Q$227*'5_TFIDF'!V$227) | I21: =SUMPRODUCT('5_TFIDF'!$Q$6:$Q$225,'5_TFIDF'!$W$6:$W$225)/('5_TFIDF'!Q$227*'5_TFIDF'!W$227) | J21: =SUMPRODUCT('5_TFIDF'!$Q$6:$Q$225,'5_TFIDF'!$X$6:$X$225)/('5_TFIDF'!Q$227*'5_TFIDF'!X$227) | K21: =SUMPRODUCT('5_TFIDF'!$Q$6:$Q$225,'5_TFIDF'!$Y$6:$Y$225)/('5_TFIDF'!Q$227*'5_TFIDF'!Y$227) | L21: =SUMPRODUCT('5_TFIDF'!$Q$6:$Q$225,'5_TFIDF'!$Z$6:$Z$225)/('5_TFIDF'!Q$227*'5_TFIDF'!Z$227) | M21: =SUMPRODUCT('5_TFIDF'!$Q$6:$Q$225,'5_TFIDF'!$AA$6:$AA$225)/('5_TFIDF'!Q$227*'5_TFIDF'!AA$227)
A22: pos 3 | B22: =SUMPRODUCT('5_TFIDF'!$R$6:$R$225,'5_TFIDF'!$P$6:$P$225)/('5_TFIDF'!R$227*'5_TFIDF'!P$227) | C22: =SUMPRODUCT('5_TFIDF'!$R$6:$R$225,'5_TFIDF'!$Q$6:$Q$225)/('5_TFIDF'!R$227*'5_TFIDF'!Q$227) | D22: =SUMPRODUCT('5_TFIDF'!$R$6:$R$225,'5_TFIDF'!$R$6:$R$225)/('5_TFIDF'!R$227*'5_TFIDF'!R$227) | E22: =SUMPRODUCT('5_TFIDF'!$R$6:$R$225,'5_TFIDF'!$S$6:$S$225)/('5_TFIDF'!R$227*'5_TFIDF'!S$227) | F22: =SUMPRODUCT('5_TFIDF'!$R$6:$R$225,'5_TFIDF'!$T$6:$T$225)/('5_TFIDF'!R$227*'5_TFIDF'!T$227) | G22: =SUMPRODUCT('5_TFIDF'!$R$6:$R$225,'5_TFIDF'!$U$6:$U$225)/('5_TFIDF'!R$227*'5_TFIDF'!U$227) | H22: =SUMPRODUCT('5_TFIDF'!$R$6:$R$225,'5_TFIDF'!$V$6:$V$225)/('5_TFIDF'!R$227*'5_TFIDF'!V$227) | I22: =SUMPRODUCT('5_TFIDF'!$R$6:$R$225,'5_TFIDF'!$W$6:$W$225)/('5_TFIDF'!R$227*'5_TFIDF'!W$227) | J22: =SUMPRODUCT('5_TFIDF'!$R$6:$R$225,'5_TFIDF'!$X$6:$X$225)/('5_TFIDF'!R$227*'5_TFIDF'!X$227) | K22: =SUMPRODUCT('5_TFIDF'!$R$6:$R$225,'5_TFIDF'!$Y$6:$Y$225)/('5_TFIDF'!R$227*'5_TFIDF'!Y$227) | L22: =SUMPRODUCT('5_TFIDF'!$R$6:$R$225,'5_TFIDF'!$Z$6:$Z$225)/('5_TFIDF'!R$227*'5_TFIDF'!Z$227) | M22: =SUMPRODUCT('5_TFIDF'!$R$6:$R$225,'5_TFIDF'!$AA$6:$AA$225)/('5_TFIDF'!R$227*'5_TFIDF'!AA$227)
A23: pos 4 | B23: =SUMPRODUCT('5_TFIDF'!$S$6:$S$225,'5_TFIDF'!$P$6:$P$225)/('5_TFIDF'!S$227*'5_TFIDF'!P$227) | C23: =SUMPRODUCT('5_TFIDF'!$S$6:$S$225,'5_TFIDF'!$Q$6:$Q$225)/('5_TFIDF'!S$227*'5_TFIDF'!Q$227) | D23: =SUMPRODUCT('5_TFIDF'!$S$6:$S$225,'5_TFIDF'!$R$6:$R$225)/('5_TFIDF'!S$227*'5_TFIDF'!R$227) | E23: =SUMPRODUCT('5_TFIDF'!$S$6:$S$225,'5_TFIDF'!$S$6:$S$225)/('5_TFIDF'!S$227*'5_TFIDF'!S$227) | F23: =SUMPRODUCT('5_TFIDF'!$S$6:$S$225,'5_TFIDF'!$T$6:$T$225)/('5_TFIDF'!S$227*'5_TFIDF'!T$227) | G23: =SUMPRODUCT('5_TFIDF'!$S$6:$S$225,'5_TFIDF'!$U$6:$U$225)/('5_TFIDF'!S$227*'5_TFIDF'!U$227) | H23: =SUMPRODUCT('5_TFIDF'!$S$6:$S$225,'5_TFIDF'!$V$6:$V$225)/('5_TFIDF'!S$227*'5_TFIDF'!V$227) | I23: =SUMPRODUCT('5_TFIDF'!$S$6:$S$225,'5_TFIDF'!$W$6:$W$225)/('5_TFIDF'!S$227*'5_TFIDF'!W$227) | J23: =SUMPRODUCT('5_TFIDF'!$S$6:$S$225,'5_TFIDF'!$X$6:$X$225)/('5_TFIDF'!S$227*'5_TFIDF'!X$227) | K23: =SUMPRODUCT('5_TFIDF'!$S$6:$S$225,'5_TFIDF'!$Y$6:$Y$225)/('5_TFIDF'!S$227*'5_TFIDF'!Y$227) | L23: =SUMPRODUCT('5_TFIDF'!$S$6:$S$225,'5_TFIDF'!$Z$6:$Z$225)/('5_TFIDF'!S$227*'5_TFIDF'!Z$227) | M23: =SUMPRODUCT('5_TFIDF'!$S$6:$S$225,'5_TFIDF'!$AA$6:$AA$225)/('5_TFIDF'!S$227*'5_TFIDF'!AA$227)
A24: pos 5 | B24: =SUMPRODUCT('5_TFIDF'!$T$6:$T$225,'5_TFIDF'!$P$6:$P$225)/('5_TFIDF'!T$227*'5_TFIDF'!P$227) | C24: =SUMPRODUCT('5_TFIDF'!$T$6:$T$225,'5_TFIDF'!$Q$6:$Q$225)/('5_TFIDF'!T$227*'5_TFIDF'!Q$227) | D24: =SUMPRODUCT('5_TFIDF'!$T$6:$T$225,'5_TFIDF'!$R$6:$R$225)/('5_TFIDF'!T$227*'5_TFIDF'!R$227) | E24: =SUMPRODUCT('5_TFIDF'!$T$6:$T$225,'5_TFIDF'!$S$6:$S$225)/('5_TFIDF'!T$227*'5_TFIDF'!S$227) | F24: =SUMPRODUCT('5_TFIDF'!$T$6:$T$225,'5_TFIDF'!$T$6:$T$225)/('5_TFIDF'!T$227*'5_TFIDF'!T$227) | G24: =SUMPRODUCT('5_TFIDF'!$T$6:$T$225,'5_TFIDF'!$U$6:$U$225)/('5_TFIDF'!T$227*'5_TFIDF'!U$227) | H24: =SUMPRODUCT('5_TFIDF'!$T$6:$T$225,'5_TFIDF'!$V$6:$V$225)/('5_TFIDF'!T$227*'5_TFIDF'!V$227) | I24: =SUMPRODUCT('5_TFIDF'!$T$6:$T$225,'5_TFIDF'!$W$6:$W$225)/('5_TFIDF'!T$227*'5_TFIDF'!W$227) | J24: =SUMPRODUCT('5_TFIDF'!$T$6:$T$225,'5_TFIDF'!$X$6:$X$225)/('5_TFIDF'!T$227*'5_TFIDF'!X$227) | K24: =SUMPRODUCT('5_TFIDF'!$T$6:$T$225,'5_TFIDF'!$Y$6:$Y$225)/('5_TFIDF'!T$227*'5_TFIDF'!Y$227) | L24: =SUMPRODUCT('5_TFIDF'!$T$6:$T$225,'5_TFIDF'!$Z$6:$Z$225)/('5_TFIDF'!T$227*'5_TFIDF'!Z$227) | M24: =SUMPRODUCT('5_TFIDF'!$T$6:$T$225,'5_TFIDF'!$AA$6:$AA$225)/('5_TFIDF'!T$227*'5_TFIDF'!AA$227)
A25: pos 6 | B25: =SUMPRODUCT('5_TFIDF'!$U$6:$U$225,'5_TFIDF'!$P$6:$P$225)/('5_TFIDF'!U$227*'5_TFIDF'!P$227) | C25: =SUMPRODUCT('5_TFIDF'!$U$6:$U$225,'5_TFIDF'!$Q$6:$Q$225)/('5_TFIDF'!U$227*'5_TFIDF'!Q$227) | D25: =SUMPRODUCT('5_TFIDF'!$U$6:$U$225,'5_TFIDF'!$R$6:$R$225)/('5_TFIDF'!U$227*'5_TFIDF'!R$227) | E25: =SUMPRODUCT('5_TFIDF'!$U$6:$U$225,'5_TFIDF'!$S$6:$S$225)/('5_TFIDF'!U$227*'5_TFIDF'!S$227) | F25: =SUMPRODUCT('5_TFIDF'!$U$6:$U$225,'5_TFIDF'!$T$6:$T$225)/('5_TFIDF'!U$227*'5_TFIDF'!T$227) | G25: =SUMPRODUCT('5_TFIDF'!$U$6:$U$225,'5_TFIDF'!$U$6:$U$225)/('5_TFIDF'!U$227*'5_TFIDF'!U$227) | H25: =SUMPRODUCT('5_TFIDF'!$U$6:$U$225,'5_TFIDF'!$V$6:$V$225)/('5_TFIDF'!U$227*'5_TFIDF'!V$227) | I25: =SUMPRODUCT('5_TFIDF'!$U$6:$U$225,'5_TFIDF'!$W$6:$W$225)/('5_TFIDF'!U$227*'5_TFIDF'!W$227) | J25: =SUMPRODUCT('5_TFIDF'!$U$6:$U$225,'5_TFIDF'!$X$6:$X$225)/('5_TFIDF'!U$227*'5_TFIDF'!X$227) | K25: =SUMPRODUCT('5_TFIDF'!$U$6:$U$225,'5_TFIDF'!$Y$6:$Y$225)/('5_TFIDF'!U$227*'5_TFIDF'!Y$227) | L25: =SUMPRODUCT('5_TFIDF'!$U$6:$U$225,'5_TFIDF'!$Z$6:$Z$225)/('5_TFIDF'!U$227*'5_TFIDF'!Z$227) | M25: =SUMPRODUCT('5_TFIDF'!$U$6:$U$225,'5_TFIDF'!$AA$6:$AA$225)/('5_TFIDF'!U$227*'5_TFIDF'!AA$227)
A26: pos 7 | B26: =SUMPRODUCT('5_TFIDF'!$V$6:$V$225,'5_TFIDF'!$P$6:$P$225)/('5_TFIDF'!V$227*'5_TFIDF'!P$227) | C26: =SUMPRODUCT('5_TFIDF'!$V$6:$V$225,'5_TFIDF'!$Q$6:$Q$225)/('5_TFIDF'!V$227*'5_TFIDF'!Q$227) | D26: =SUMPRODUCT('5_TFIDF'!$V$6:$V$225,'5_TFIDF'!$R$6:$R$225)/('5_TFIDF'!V$227*'5_TFIDF'!R$227) | E26: =SUMPRODUCT('5_TFIDF'!$V$6:$V$225,'5_TFIDF'!$S$6:$S$225)/('5_TFIDF'!V$227*'5_TFIDF'!S$227) | F26: =SUMPRODUCT('5_TFIDF'!$V$6:$V$225,'5_TFIDF'!$T$6:$T$225)/('5_TFIDF'!V$227*'5_TFIDF'!T$227) | G26: =SUMPRODUCT('5_TFIDF'!$V$6:$V$225,'5_TFIDF'!$U$6:$U$225)/('5_TFIDF'!V$227*'5_TFIDF'!U$227) | H26: =SUMPRODUCT('5_TFIDF'!$V$6:$V$225,'5_TFIDF'!$V$6:$V$225)/('5_TFIDF'!V$227*'5_TFIDF'!V$227) | I26: =SUMPRODUCT('5_TFIDF'!$V$6:$V$225,'5_TFIDF'!$W$6:$W$225)/('5_TFIDF'!V$227*'5_TFIDF'!W$227) | J26: =SUMPRODUCT('5_TFIDF'!$V$6:$V$225,'5_TFIDF'!$X$6:$X$225)/('5_TFIDF'!V$227*'5_TFIDF'!X$227) | K26: =SUMPRODUCT('5_TFIDF'!$V$6:$V$225,'5_TFIDF'!$Y$6:$Y$225)/('5_TFIDF'!V$227*'5_TFIDF'!Y$227) | L26: =SUMPRODUCT('5_TFIDF'!$V$6:$V$225,'5_TFIDF'!$Z$6:$Z$225)/('5_TFIDF'!V$227*'5_TFIDF'!Z$227) | M26: =SUMPRODUCT('5_TFIDF'!$V$6:$V$225,'5_TFIDF'!$AA$6:$AA$225)/('5_TFIDF'!V$227*'5_TFIDF'!AA$227)
A27: pos 8 | B27: =SUMPRODUCT('5_TFIDF'!$W$6:$W$225,'5_TFIDF'!$P$6:$P$225)/('5_TFIDF'!W$227*'5_TFIDF'!P$227) | C27: =SUMPRODUCT('5_TFIDF'!$W$6:$W$225,'5_TFIDF'!$Q$6:$Q$225)/('5_TFIDF'!W$227*'5_TFIDF'!Q$227) | D27: =SUMPRODUCT('5_TFIDF'!$W$6:$W$225,'5_TFIDF'!$R$6:$R$225)/('5_TFIDF'!W$227*'5_TFIDF'!R$227) | E27: =SUMPRODUCT('5_TFIDF'!$W$6:$W$225,'5_TFIDF'!$S$6:$S$225)/('5_TFIDF'!W$227*'5_TFIDF'!S$227) | F27: =SUMPRODUCT('5_TFIDF'!$W$6:$W$225,'5_TFIDF'!$T$6:$T$225)/('5_TFIDF'!W$227*'5_TFIDF'!T$227) | G27: =SUMPRODUCT('5_TFIDF'!$W$6:$W$225,'5_TFIDF'!$U$6:$U$225)/('5_TFIDF'!W$227*'5_TFIDF'!U$227) | H27: =SUMPRODUCT('5_TFIDF'!$W$6:$W$225,'5_TFIDF'!$V$6:$V$225)/('5_TFIDF'!W$227*'5_TFIDF'!V$227) | I27: =SUMPRODUCT('5_TFIDF'!$W$6:$W$225,'5_TFIDF'!$W$6:$W$225)/('5_TFIDF'!W$227*'5_TFIDF'!W$227) | J27: =SUMPRODUCT('5_TFIDF'!$W$6:$W$225,'5_TFIDF'!$X$6:$X$225)/('5_TFIDF'!W$227*'5_TFIDF'!X$227) | K27: =SUMPRODUCT('5_TFIDF'!$W$6:$W$225,'5_TFIDF'!$Y$6:$Y$225)/('5_TFIDF'!W$227*'5_TFIDF'!Y$227) | L27: =SUMPRODUCT('5_TFIDF'!$W$6:$W$225,'5_TFIDF'!$Z$6:$Z$225)/('5_TFIDF'!W$227*'5_TFIDF'!Z$227) | M27: =SUMPRODUCT('5_TFIDF'!$W$6:$W$225,'5_TFIDF'!$AA$6:$AA$225)/('5_TFIDF'!W$227*'5_TFIDF'!AA$227)
A28: pos 9 | B28: =SUMPRODUCT('5_TFIDF'!$X$6:$X$225,'5_TFIDF'!$P$6:$P$225)/('5_TFIDF'!X$227*'5_TFIDF'!P$227) | C28: =SUMPRODUCT('5_TFIDF'!$X$6:$X$225,'5_TFIDF'!$Q$6:$Q$225)/('5_TFIDF'!X$227*'5_TFIDF'!Q$227) | D28: =SUMPRODUCT('5_TFIDF'!$X$6:$X$225,'5_TFIDF'!$R$6:$R$225)/('5_TFIDF'!X$227*'5_TFIDF'!R$227) | E28: =SUMPRODUCT('5_TFIDF'!$X$6:$X$225,'5_TFIDF'!$S$6:$S$225)/('5_TFIDF'!X$227*'5_TFIDF'!S$227) | F28: =SUMPRODUCT('5_TFIDF'!$X$6:$X$225,'5_TFIDF'!$T$6:$T$225)/('5_TFIDF'!X$227*'5_TFIDF'!T$227) | G28: =SUMPRODUCT('5_TFIDF'!$X$6:$X$225,'5_TFIDF'!$U$6:$U$225)/('5_TFIDF'!X$227*'5_TFIDF'!U$227) | H28: =SUMPRODUCT('5_TFIDF'!$X$6:$X$225,'5_TFIDF'!$V$6:$V$225)/('5_TFIDF'!X$227*'5_TFIDF'!V$227) | I28: =SUMPRODUCT('5_TFIDF'!$X$6:$X$225,'5_TFIDF'!$W$6:$W$225)/('5_TFIDF'!X$227*'5_TFIDF'!W$227) | J28: =SUMPRODUCT('5_TFIDF'!$X$6:$X$225,'5_TFIDF'!$X$6:$X$225)/('5_TFIDF'!X$227*'5_TFIDF'!X$227) | K28: =SUMPRODUCT('5_TFIDF'!$X$6:$X$225,'5_TFIDF'!$Y$6:$Y$225)/('5_TFIDF'!X$227*'5_TFIDF'!Y$227) | L28: =SUMPRODUCT('5_TFIDF'!$X$6:$X$225,'5_TFIDF'!$Z$6:$Z$225)/('5_TFIDF'!X$227*'5_TFIDF'!Z$227) | M28: =SUMPRODUCT('5_TFIDF'!$X$6:$X$225,'5_TFIDF'!$AA$6:$AA$225)/('5_TFIDF'!X$227*'5_TFIDF'!AA$227)
A29: pos 10 | B29: =SUMPRODUCT('5_TFIDF'!$Y$6:$Y$225,'5_TFIDF'!$P$6:$P$225)/('5_TFIDF'!Y$227*'5_TFIDF'!P$227) | C29: =SUMPRODUCT('5_TFIDF'!$Y$6:$Y$225,'5_TFIDF'!$Q$6:$Q$225)/('5_TFIDF'!Y$227*'5_TFIDF'!Q$227) | D29: =SUMPRODUCT('5_TFIDF'!$Y$6:$Y$225,'5_TFIDF'!$R$6:$R$225)/('5_TFIDF'!Y$227*'5_TFIDF'!R$227) | E29: =SUMPRODUCT('5_TFIDF'!$Y$6:$Y$225,'5_TFIDF'!$S$6:$S$225)/('5_TFIDF'!Y$227*'5_TFIDF'!S$227) | F29: =SUMPRODUCT('5_TFIDF'!$Y$6:$Y$225,'5_TFIDF'!$T$6:$T$225)/('5_TFIDF'!Y$227*'5_TFIDF'!T$227) | G29: =SUMPRODUCT('5_TFIDF'!$Y$6:$Y$225,'5_TFIDF'!$U$6:$U$225)/('5_TFIDF'!Y$227*'5_TFIDF'!U$227) | H29: =SUMPRODUCT('5_TFIDF'!$Y$6:$Y$225,'5_TFIDF'!$V$6:$V$225)/('5_TFIDF'!Y$227*'5_TFIDF'!V$227) | I29: =SUMPRODUCT('5_TFIDF'!$Y$6:$Y$225,'5_TFIDF'!$W$6:$W$225)/('5_TFIDF'!Y$227*'5_TFIDF'!W$227) | J29: =SUMPRODUCT('5_TFIDF'!$Y$6:$Y$225,'5_TFIDF'!$X$6:$X$225)/('5_TFIDF'!Y$227*'5_TFIDF'!X$227) | K29: =SUMPRODUCT('5_TFIDF'!$Y$6:$Y$225,'5_TFIDF'!$Y$6:$Y$225)/('5_TFIDF'!Y$227*'5_TFIDF'!Y$227) | L29: =SUMPRODUCT('5_TFIDF'!$Y$6:$Y$225,'5_TFIDF'!$Z$6:$Z$225)/('5_TFIDF'!Y$227*'5_TFIDF'!Z$227) | M29: =SUMPRODUCT('5_TFIDF'!$Y$6:$Y$225,'5_TFIDF'!$AA$6:$AA$225)/('5_TFIDF'!Y$227*'5_TFIDF'!AA$227)
A30: pos 11 | B30: =SUMPRODUCT('5_TFIDF'!$Z$6:$Z$225,'5_TFIDF'!$P$6:$P$225)/('5_TFIDF'!Z$227*'5_TFIDF'!P$227) | C30: =SUMPRODUCT('5_TFIDF'!$Z$6:$Z$225,'5_TFIDF'!$Q$6:$Q$225)/('5_TFIDF'!Z$227*'5_TFIDF'!Q$227) | D30: =SUMPRODUCT('5_TFIDF'!$Z$6:$Z$225,'5_TFIDF'!$R$6:$R$225)/('5_TFIDF'!Z$227*'5_TFIDF'!R$227) | E30: =SUMPRODUCT('5_TFIDF'!$Z$6:$Z$225,'5_TFIDF'!$S$6:$S$225)/('5_TFIDF'!Z$227*'5_TFIDF'!S$227) | F30: =SUMPRODUCT('5_TFIDF'!$Z$6:$Z$225,'5_TFIDF'!$T$6:$T$225)/('5_TFIDF'!Z$227*'5_TFIDF'!T$227) | G30: =SUMPRODUCT('5_TFIDF'!$Z$6:$Z$225,'5_TFIDF'!$U$6:$U$225)/('5_TFIDF'!Z$227*'5_TFIDF'!U$227) | H30: =SUMPRODUCT('5_TFIDF'!$Z$6:$Z$225,'5_TFIDF'!$V$6:$V$225)/('5_TFIDF'!Z$227*'5_TFIDF'!V$227) | I30: =SUMPRODUCT('5_TFIDF'!$Z$6:$Z$225,'5_TFIDF'!$W$6:$W$225)/('5_TFIDF'!Z$227*'5_TFIDF'!W$227) | J30: =SUMPRODUCT('5_TFIDF'!$Z$6:$Z$225,'5_TFIDF'!$X$6:$X$225)/('5_TFIDF'!Z$227*'5_TFIDF'!X$227) | K30: =SUMPRODUCT('5_TFIDF'!$Z$6:$Z$225,'5_TFIDF'!$Y$6:$Y$225)/('5_TFIDF'!Z$227*'5_TFIDF'!Y$227) | L30: =SUMPRODUCT('5_TFIDF'!$Z$6:$Z$225,'5_TFIDF'!$Z$6:$Z$225)/('5_TFIDF'!Z$227*'5_TFIDF'!Z$227) | M30: =SUMPRODUCT('5_TFIDF'!$Z$6:$Z$225,'5_TFIDF'!$AA$6:$AA$225)/('5_TFIDF'!Z$227*'5_TFIDF'!AA$227)
A31: pos 12 | B31: =SUMPRODUCT('5_TFIDF'!$AA$6:$AA$225,'5_TFIDF'!$P$6:$P$225)/('5_TFIDF'!AA$227*'5_TFIDF'!P$227) | C31: =SUMPRODUCT('5_TFIDF'!$AA$6:$AA$225,'5_TFIDF'!$Q$6:$Q$225)/('5_TFIDF'!AA$227*'5_TFIDF'!Q$227) | D31: =SUMPRODUCT('5_TFIDF'!$AA$6:$AA$225,'5_TFIDF'!$R$6:$R$225)/('5_TFIDF'!AA$227*'5_TFIDF'!R$227) | E31: =SUMPRODUCT('5_TFIDF'!$AA$6:$AA$225,'5_TFIDF'!$S$6:$S$225)/('5_TFIDF'!AA$227*'5_TFIDF'!S$227) | F31: =SUMPRODUCT('5_TFIDF'!$AA$6:$AA$225,'5_TFIDF'!$T$6:$T$225)/('5_TFIDF'!AA$227*'5_TFIDF'!T$227) | G31: =SUMPRODUCT('5_TFIDF'!$AA$6:$AA$225,'5_TFIDF'!$U$6:$U$225)/('5_TFIDF'!AA$227*'5_TFIDF'!U$227) | H31: =SUMPRODUCT('5_TFIDF'!$AA$6:$AA$225,'5_TFIDF'!$V$6:$V$225)/('5_TFIDF'!AA$227*'5_TFIDF'!V$227) | I31: =SUMPRODUCT('5_TFIDF'!$AA$6:$AA$225,'5_TFIDF'!$W$6:$W$225)/('5_TFIDF'!AA$227*'5_TFIDF'!W$227) | J31: =SUMPRODUCT('5_TFIDF'!$AA$6:$AA$225,'5_TFIDF'!$X$6:$X$225)/('5_TFIDF'!AA$227*'5_TFIDF'!X$227) | K31: =SUMPRODUCT('5_TFIDF'!$AA$6:$AA$225,'5_TFIDF'!$Y$6:$Y$225)/('5_TFIDF'!AA$227*'5_TFIDF'!Y$227) | L31: =SUMPRODUCT('5_TFIDF'!$AA$6:$AA$225,'5_TFIDF'!$Z$6:$Z$225)/('5_TFIDF'!AA$227*'5_TFIDF'!Z$227) | M31: =SUMPRODUCT('5_TFIDF'!$AA$6:$AA$225,'5_TFIDF'!$AA$6:$AA$225)/('5_TFIDF'!AA$227*'5_TFIDF'!AA$227)

Sheet 7_CBF
A1: 7 - Peringkat Content-Based Filtering
A2: Skor CBF = kosinus ke profil sesi (6_Cosine). Artikel yang sudah dibaca dibuang; idx 0 = teratas, sama seperti urutan _top di serving.py.
A4: Pos | B4: nid | C4: Sesi? | D4: Skor CBF | E4: idx CBF | F4: Peringkat
A5: 1 | B5: I2d5df0726f | C5: ='6_Cosine'!C5 | D5: ='6_Cosine'!D5 | E5: =IF(C5="Ya","",COUNTIFS($D$5:$D$16,">"&D5,$C$5:$C$16,"<>Ya")+COUNTIFS($D$5:$D$16,D5,$C$5:$C$16,"<>Ya",$A$5:$A$16,"<"&A5)) | F5: =IF(E5="","",E5+1)
A6: 2 | B6: I0f3340d602 | C6: ='6_Cosine'!C6 | D6: ='6_Cosine'!D6 | E6: =IF(C6="Ya","",COUNTIFS($D$5:$D$16,">"&D6,$C$5:$C$16,"<>Ya")+COUNTIFS($D$5:$D$16,D6,$C$5:$C$16,"<>Ya",$A$5:$A$16,"<"&A6)) | F6: =IF(E6="","",E6+1)
A7: 3 | B7: Ic3f4f2512e | C7: ='6_Cosine'!C7 | D7: ='6_Cosine'!D7 | E7: =IF(C7="Ya","",COUNTIFS($D$5:$D$16,">"&D7,$C$5:$C$16,"<>Ya")+COUNTIFS($D$5:$D$16,D7,$C$5:$C$16,"<>Ya",$A$5:$A$16,"<"&A7)) | F7: =IF(E7="","",E7+1)
A8: 4 | B8: Ifa9f81c923 | C8: ='6_Cosine'!C8 | D8: ='6_Cosine'!D8 | E8: =IF(C8="Ya","",COUNTIFS($D$5:$D$16,">"&D8,$C$5:$C$16,"<>Ya")+COUNTIFS($D$5:$D$16,D8,$C$5:$C$16,"<>Ya",$A$5:$A$16,"<"&A8)) | F8: =IF(E8="","",E8+1)
A9: 5 | B9: I1d82a5e6ee | C9: ='6_Cosine'!C9 | D9: ='6_Cosine'!D9 | E9: =IF(C9="Ya","",COUNTIFS($D$5:$D$16,">"&D9,$C$5:$C$16,"<>Ya")+COUNTIFS($D$5:$D$16,D9,$C$5:$C$16,"<>Ya",$A$5:$A$16,"<"&A9)) | F9: =IF(E9="","",E9+1)
A10: 6 | B10: Ib13654bb81 | C10: ='6_Cosine'!C10 | D10: ='6_Cosine'!D10 | E10: =IF(C10="Ya","",COUNTIFS($D$5:$D$16,">"&D10,$C$5:$C$16,"<>Ya")+COUNTIFS($D$5:$D$16,D10,$C$5:$C$16,"<>Ya",$A$5:$A$16,"<"&A10)) | F10: =IF(E10="","",E10+1)
A11: 7 | B11: I5259c70cfc | C11: ='6_Cosine'!C11 | D11: ='6_Cosine'!D11 | E11: =IF(C11="Ya","",COUNTIFS($D$5:$D$16,">"&D11,$C$5:$C$16,"<>Ya")+COUNTIFS($D$5:$D$16,D11,$C$5:$C$16,"<>Ya",$A$5:$A$16,"<"&A11)) | F11: =IF(E11="","",E11+1)
A12: 8 | B12: I67dbbb2a6e | C12: ='6_Cosine'!C12 | D12: ='6_Cosine'!D12 | E12: =IF(C12="Ya","",COUNTIFS($D$5:$D$16,">"&D12,$C$5:$C$16,"<>Ya")+COUNTIFS($D$5:$D$16,D12,$C$5:$C$16,"<>Ya",$A$5:$A$16,"<"&A12)) | F12: =IF(E12="","",E12+1)
A13: 9 | B13: I307e7d7249 | C13: ='6_Cosine'!C13 | D13: ='6_Cosine'!D13 | E13: =IF(C13="Ya","",COUNTIFS($D$5:$D$16,">"&D13,$C$5:$C$16,"<>Ya")+COUNTIFS($D$5:$D$16,D13,$C$5:$C$16,"<>Ya",$A$5:$A$16,"<"&A13)) | F13: =IF(E13="","",E13+1)
A14: 10 | B14: I99144f9b4e | C14: ='6_Cosine'!C14 | D14: ='6_Cosine'!D14 | E14: =IF(C14="Ya","",COUNTIFS($D$5:$D$16,">"&D14,$C$5:$C$16,"<>Ya")+COUNTIFS($D$5:$D$16,D14,$C$5:$C$16,"<>Ya",$A$5:$A$16,"<"&A14)) | F14: =IF(E14="","",E14+1)
A15: 11 | B15: I01684f5bad | C15: ='6_Cosine'!C15 | D15: ='6_Cosine'!D15 | E15: =IF(C15="Ya","",COUNTIFS($D$5:$D$16,">"&D15,$C$5:$C$16,"<>Ya")+COUNTIFS($D$5:$D$16,D15,$C$5:$C$16,"<>Ya",$A$5:$A$16,"<"&A15)) | F15: =IF(E15="","",E15+1)
A16: 12 | B16: I18ca3d0ae0 | C16: ='6_Cosine'!C16 | D16: ='6_Cosine'!D16 | E16: =IF(C16="Ya","",COUNTIFS($D$5:$D$16,">"&D16,$C$5:$C$16,"<>Ya")+COUNTIFS($D$5:$D$16,D16,$C$5:$C$16,"<>Ya",$A$5:$A$16,"<"&A16)) | F16: =IF(E16="","",E16+1)

Sheet 8_ALS
A1: 8 - Skor Collaborative Filtering (implicit ALS)
A2: 128 faktor laten per artikel adalah baris nyata dari indo_als_item_factors.npy (dibulatkan 6 desimal). Kolom profil = AVERAGE faktor 3 artikel sesi, jalur cold session pada _als_scores. Skor = SUMPRODUCT(faktor artikel, profil).
A4: Dim | B4: f pos 1 | C4: f pos 2 | D4: f pos 3 | E4: f pos 4 | F4: f pos 5 | G4: f pos 6 | H4: f pos 7 | I4: f pos 8 | J4: f pos 9 | K4: f pos 10 | L4: f pos 11 | M4: f pos 12 | N4: profil
A5: 1 | B5: -0.001258 | C5: 0.0040799999 | D5: 0.002264 | E5: 0.00046400001 | F5: 0.0058019999 | G5: 0.011269 | H5: 0.0024959999 | I5: 0.003243 | J5: 0.010283 | K5: 0.0020270001 | L5: 0.010312 | M5: 0.001763 | N5: =AVERAGE(B5,C5,E5)
A6: 2 | B6: 0.00153 | C6: 0.001258 | D6: 0.0019700001 | E6: 0.0037380001 | F6: 0.00026199999 | G6: 0.012387 | H6: 0.003334 | I6: -0.001908 | J6: 0.0057370001 | K6: 0.00028899999 | L6: 0.013699 | M6: 0.001127 | N6: =AVERAGE(B6,C6,E6)
A7: 3 | B7: 0.00089600001 | C7: 0.0074080001 | D7: 0.002846 | E7: 0.00041499999 | F7: 0.0092259999 | G7: 0.0068020001 | H7: 0.004799 | I7: -0.00075100001 | J7: -0.001886 | K7: 0.000802 | L7: 0.0081240004 | M7: 0.0032319999 | N7: =AVERAGE(B7,C7,E7)
A8: 4 | B8: 0.002569 | C8: 0.001746 | D8: -0.0026370001 | E8: -0.001269 | F8: 0.002137 | G8: -0.003058 | H8: -0.003787 | I8: -0.002451 | J8: -0.0054350002 | K8: 0.0023350001 | L8: 0.000657 | M8: 0.000994 | N8: =AVERAGE(B8,C8,E8)
A9: 5 | B9: 0.0051449998 | C9: 0.001951 | D9: -0.0033249999 | E9: -0.0033420001 | F9: 0.00062599999 | G9: 0.00021899999 | H9: 0.001164 | I9: 0.00050899998 | J9: 0.0036279999 | K9: 0.001569 | L9: 0.0067030001 | M9: 0.0035910001 | N9: =AVERAGE(B9,C9,E9)
A10: 6 | B10: 0.0058809998 | C10: 0.0028669999 | D10: 0.0065680002 | E10: 0.002051 | F10: 0.002109 | G10: 0.0039369999 | H10: 0.0026110001 | I10: -0.001454 | J10: 0.0036770001 | K10: -0.001175 | L10: 0.0035649999 | M10: -0.000424 | N10: =AVERAGE(B10,C10,E10)
A11: 7 | B11: -0.0033420001 | C11: 0.0041399999 | D11: -0.00073500001 | E11: 0.002813 | F11: 0.002533 | G11: 0.0021899999 | H11: 0.003143 | I11: 0.00165 | J11: 0.006668 | K11: 0.001135 | L11: 0.0072420002 | M11: -0.001406 | N11: =AVERAGE(B11,C11,E11)
A12: 8 | B12: -0.0024540001 | C12: 0.0033839999 | D12: 0.003669 | E12: -0.00077599997 | F12: -0.00085000001 | G12: 0.0041240002 | H12: 0.0033509999 | I12: -0.00093400001 | J12: 0.0058849999 | K12: 0.0043970002 | L12: 0.0071129999 | M12: -0.000157 | N12: =AVERAGE(B12,C12,E12)
A13: 9 | B13: 0.002105 | C13: 0.00053100003 | D13: 0.001534 | E13: 0.001348 | F13: 0.0025810001 | G13: 0.0064750002 | H13: 0.003184 | I13: -0.00034500001 | J13: 0.0020699999 | K13: 0.0024629999 | L13: 0.0073779998 | M13: 0.00352 | N13: =AVERAGE(B13,C13,E13)
A14: 10 | B14: -0.00052599999 | C14: 0.0056650001 | D14: 0.0024689999 | E14: 0.001746 | F14: 0.0054799998 | G14: -0.0075759999 | H14: 0.0023630001 | I14: -0.0033539999 | J14: 0.0041470001 | K14: 0.0040839999 | L14: 0.0029420001 | M14: 0.003724 | N14: =AVERAGE(B14,C14,E14)
A15: 11 | B15: -0.001407 | C15: 0.0043959999 | D15: 0.0021899999 | E15: 0.0020389999 | F15: 0.0033730001 | G15: -0.0022499999 | H15: 0.0014140001 | I15: -0.00085299998 | J15: -0.002013 | K15: 0.001379 | L15: 0.000917 | M15: 0.0032210001 | N15: =AVERAGE(B15,C15,E15)
A16: 12 | B16: 0.0038940001 | C16: 0.0040770001 | D16: 0.005196 | E16: 0.0049729999 | F16: 0.00012300001 | G16: -0.00039999999 | H16: -0.00075800001 | I16: 0.00085800001 | J16: 0.0095229996 | K16: -0.00079700002 | L16: 0.001452 | M16: -0.000719 | N16: =AVERAGE(B16,C16,E16)
... A132: 128 | B132: 4.8000002e-05 | C132: 0.0045989999 | D132: 0.001079 | E132: 0.0058610002 | F132: 0.006941 | G132: 0.0094569996 | H132: 0.0024270001 | I132: 0.00071499997 | J132: 0.00071599998 | K132: 0.0020079999 | L132: -0.0080239996 | M132: 0.00048799999 | N132: =AVERAGE(B132,C132,E132)
A134: skor ALS | B134: =SUMPRODUCT(N5:N132,B5:B132) | C134: =SUMPRODUCT(N5:N132,C5:C132) | D134: =SUMPRODUCT(N5:N132,D5:D132) | E134: =SUMPRODUCT(N5:N132,E5:E132) | F134: =SUMPRODUCT(N5:N132,F5:F132) | G134: =SUMPRODUCT(N5:N132,G5:G132) | H134: =SUMPRODUCT(N5:N132,H5:H132) | I134: =SUMPRODUCT(N5:N132,I5:I132) | J134: =SUMPRODUCT(N5:N132,J5:J132) | K134: =SUMPRODUCT(N5:N132,K5:K132) | L134: =SUMPRODUCT(N5:N132,L5:L132) | M134: =SUMPRODUCT(N5:N132,M5:M132)

Sheet 9_Hybrid
A1: 9 - Skor hybrid (alpha = 0,8) dan peringkat
A2: min-max per kolom skor mentah (BATAS 2: di sini atas 12 kandidat). Skor = alpha x minmax(ALS) + (1 - alpha) x minmax(CBF). Artikel sesi dimask persis seperti _mask di serving.py.
A4: Pos | B4: nid | C4: Sesi? | D4: skor ALS | E4: minmax ALS | F4: skor CBF | G4: minmax CBF | H4: skor hybrid | I4: dilayani? | J4: Peringkat
A5: 1 | B5: I2d5df0726f | C5: Ya | D5: ='8_ALS'!B$134 | E5: =(D5-MIN($D$5:$D$16))/(MAX($D$5:$D$16)-MIN($D$5:$D$16)) | F5: ='7_CBF'!D5 | G5: =(F5-MIN($F$5:$F$16))/(MAX($F$5:$F$16)-MIN($F$5:$F$16)) | H5: ='1_Data'!$L$5*E5+'1_Data'!$L$6*G5 | I5: =IF(C5="Ya","-","ya") | J5: =IF(I5="-","",COUNTIFS($H$5:$H$16,">"&H5,$I$5:$I$16,"<>-")+COUNTIFS($H$5:$H$16,H5,$I$5:$I$16,"<>-",$A$5:$A$16,"<"&A5)+1)
A6: 2 | B6: I0f3340d602 | C6: Ya | D6: ='8_ALS'!C$134 | E6: =(D6-MIN($D$5:$D$16))/(MAX($D$5:$D$16)-MIN($D$5:$D$16)) | F6: ='7_CBF'!D6 | G6: =(F6-MIN($F$5:$F$16))/(MAX($F$5:$F$16)-MIN($F$5:$F$16)) | H6: ='1_Data'!$L$5*E6+'1_Data'!$L$6*G6 | I6: =IF(C6="Ya","-","ya") | J6: =IF(I6="-","",COUNTIFS($H$5:$H$16,">"&H6,$I$5:$I$16,"<>-")+COUNTIFS($H$5:$H$16,H6,$I$5:$I$16,"<>-",$A$5:$A$16,"<"&A6)+1)
A7: 3 | B7: Ic3f4f2512e | C7: - | D7: ='8_ALS'!D$134 | E7: =(D7-MIN($D$5:$D$16))/(MAX($D$5:$D$16)-MIN($D$5:$D$16)) | F7: ='7_CBF'!D7 | G7: =(F7-MIN($F$5:$F$16))/(MAX($F$5:$F$16)-MIN($F$5:$F$16)) | H7: ='1_Data'!$L$5*E7+'1_Data'!$L$6*G7 | I7: =IF(C7="Ya","-","ya") | J7: =IF(I7="-","",COUNTIFS($H$5:$H$16,">"&H7,$I$5:$I$16,"<>-")+COUNTIFS($H$5:$H$16,H7,$I$5:$I$16,"<>-",$A$5:$A$16,"<"&A7)+1)
A8: 4 | B8: Ifa9f81c923 | C8: Ya | D8: ='8_ALS'!E$134 | E8: =(D8-MIN($D$5:$D$16))/(MAX($D$5:$D$16)-MIN($D$5:$D$16)) | F8: ='7_CBF'!D8 | G8: =(F8-MIN($F$5:$F$16))/(MAX($F$5:$F$16)-MIN($F$5:$F$16)) | H8: ='1_Data'!$L$5*E8+'1_Data'!$L$6*G8 | I8: =IF(C8="Ya","-","ya") | J8: =IF(I8="-","",COUNTIFS($H$5:$H$16,">"&H8,$I$5:$I$16,"<>-")+COUNTIFS($H$5:$H$16,H8,$I$5:$I$16,"<>-",$A$5:$A$16,"<"&A8)+1)
A9: 5 | B9: I1d82a5e6ee | C9: - | D9: ='8_ALS'!F$134 | E9: =(D9-MIN($D$5:$D$16))/(MAX($D$5:$D$16)-MIN($D$5:$D$16)) | F9: ='7_CBF'!D9 | G9: =(F9-MIN($F$5:$F$16))/(MAX($F$5:$F$16)-MIN($F$5:$F$16)) | H9: ='1_Data'!$L$5*E9+'1_Data'!$L$6*G9 | I9: =IF(C9="Ya","-","ya") | J9: =IF(I9="-","",COUNTIFS($H$5:$H$16,">"&H9,$I$5:$I$16,"<>-")+COUNTIFS($H$5:$H$16,H9,$I$5:$I$16,"<>-",$A$5:$A$16,"<"&A9)+1)
A10: 6 | B10: Ib13654bb81 | C10: - | D10: ='8_ALS'!G$134 | E10: =(D10-MIN($D$5:$D$16))/(MAX($D$5:$D$16)-MIN($D$5:$D$16)) | F10: ='7_CBF'!D10 | G10: =(F10-MIN($F$5:$F$16))/(MAX($F$5:$F$16)-MIN($F$5:$F$16)) | H10: ='1_Data'!$L$5*E10+'1_Data'!$L$6*G10 | I10: =IF(C10="Ya","-","ya") | J10: =IF(I10="-","",COUNTIFS($H$5:$H$16,">"&H10,$I$5:$I$16,"<>-")+COUNTIFS($H$5:$H$16,H10,$I$5:$I$16,"<>-",$A$5:$A$16,"<"&A10)+1)
A11: 7 | B11: I5259c70cfc | C11: - | D11: ='8_ALS'!H$134 | E11: =(D11-MIN($D$5:$D$16))/(MAX($D$5:$D$16)-MIN($D$5:$D$16)) | F11: ='7_CBF'!D11 | G11: =(F11-MIN($F$5:$F$16))/(MAX($F$5:$F$16)-MIN($F$5:$F$16)) | H11: ='1_Data'!$L$5*E11+'1_Data'!$L$6*G11 | I11: =IF(C11="Ya","-","ya") | J11: =IF(I11="-","",COUNTIFS($H$5:$H$16,">"&H11,$I$5:$I$16,"<>-")+COUNTIFS($H$5:$H$16,H11,$I$5:$I$16,"<>-",$A$5:$A$16,"<"&A11)+1)
A12: 8 | B12: I67dbbb2a6e | C12: - | D12: ='8_ALS'!I$134 | E12: =(D12-MIN($D$5:$D$16))/(MAX($D$5:$D$16)-MIN($D$5:$D$16)) | F12: ='7_CBF'!D12 | G12: =(F12-MIN($F$5:$F$16))/(MAX($F$5:$F$16)-MIN($F$5:$F$16)) | H12: ='1_Data'!$L$5*E12+'1_Data'!$L$6*G12 | I12: =IF(C12="Ya","-","ya") | J12: =IF(I12="-","",COUNTIFS($H$5:$H$16,">"&H12,$I$5:$I$16,"<>-")+COUNTIFS($H$5:$H$16,H12,$I$5:$I$16,"<>-",$A$5:$A$16,"<"&A12)+1)
A13: 9 | B13: I307e7d7249 | C13: - | D13: ='8_ALS'!J$134 | E13: =(D13-MIN($D$5:$D$16))/(MAX($D$5:$D$16)-MIN($D$5:$D$16)) | F13: ='7_CBF'!D13 | G13: =(F13-MIN($F$5:$F$16))/(MAX($F$5:$F$16)-MIN($F$5:$F$16)) | H13: ='1_Data'!$L$5*E13+'1_Data'!$L$6*G13 | I13: =IF(C13="Ya","-","ya") | J13: =IF(I13="-","",COUNTIFS($H$5:$H$16,">"&H13,$I$5:$I$16,"<>-")+COUNTIFS($H$5:$H$16,H13,$I$5:$I$16,"<>-",$A$5:$A$16,"<"&A13)+1)
A14: 10 | B14: I99144f9b4e | C14: - | D14: ='8_ALS'!K$134 | E14: =(D14-MIN($D$5:$D$16))/(MAX($D$5:$D$16)-MIN($D$5:$D$16)) | F14: ='7_CBF'!D14 | G14: =(F14-MIN($F$5:$F$16))/(MAX($F$5:$F$16)-MIN($F$5:$F$16)) | H14: ='1_Data'!$L$5*E14+'1_Data'!$L$6*G14 | I14: =IF(C14="Ya","-","ya") | J14: =IF(I14="-","",COUNTIFS($H$5:$H$16,">"&H14,$I$5:$I$16,"<>-")+COUNTIFS($H$5:$H$16,H14,$I$5:$I$16,"<>-",$A$5:$A$16,"<"&A14)+1)
